2025-04-15 14:18:41,687 - hyyb - ERROR - Exception on /auth/login [GET]
Traceback (most recent call last):
  File "E:\works\hyyb\.venv\Lib\site-packages\sqlalchemy\orm\relationships.py", line 2471, in _determine_joins
    self.primaryjoin = join_condition(
                       ^^^^^^^^^^^^^^^
  File "<string>", line 2, in join_condition
  File "<string>", line 2, in _join_condition
  File "E:\works\hyyb\.venv\Lib\site-packages\sqlalchemy\util\deprecations.py", line 128, in warned
    return fn(*args, **kwargs)
           ^^^^^^^^^^^^^^^^^^^
  File "E:\works\hyyb\.venv\Lib\site-packages\sqlalchemy\sql\selectable.py", line 949, in _join_condition
    raise exc.NoForeignKeysError(
sqlalchemy.exc.NoForeignKeysError: Can't find any foreign key relationships between 'stuff' and 'attendance'.

The above exception was the direct cause of the following exception:

Traceback (most recent call last):
  File "E:\works\hyyb\.venv\Lib\site-packages\flask\app.py", line 2447, in wsgi_app
    response = self.full_dispatch_request()
               ^^^^^^^^^^^^^^^^^^^^^^^^^^^^
  File "E:\works\hyyb\.venv\Lib\site-packages\flask\app.py", line 1952, in full_dispatch_request
    rv = self.handle_user_exception(e)
         ^^^^^^^^^^^^^^^^^^^^^^^^^^^^^
  File "E:\works\hyyb\.venv\Lib\site-packages\flask\app.py", line 1821, in handle_user_exception
    reraise(exc_type, exc_value, tb)
  File "E:\works\hyyb\.venv\Lib\site-packages\flask\_compat.py", line 39, in reraise
    raise value
  File "E:\works\hyyb\.venv\Lib\site-packages\flask\app.py", line 1950, in full_dispatch_request
    rv = self.dispatch_request()
         ^^^^^^^^^^^^^^^^^^^^^^^
  File "E:\works\hyyb\.venv\Lib\site-packages\flask\app.py", line 1936, in dispatch_request
    return self.view_functions[rule.endpoint](**req.view_args)
           ^^^^^^^^^^^^^^^^^^^^^^^^^^^^^^^^^^^^^^^^^^^^^^^^^^^
  File "E:\works\hyyb\hyyb\blueprints\auth.py", line 35, in login
    return render_template('auth/login.html', form=form) #
           ^^^^^^^^^^^^^^^^^^^^^^^^^^^^^^^^^^^^^^^^^^^^^
  File "E:\works\hyyb\.venv\Lib\site-packages\flask\templating.py", line 136, in render_template
    ctx.app.update_template_context(context)
  File "E:\works\hyyb\.venv\Lib\site-packages\flask\app.py", line 838, in update_template_context
    context.update(func())
                   ^^^^^^
  File "E:\works\hyyb\hyyb\__init__.py", line 111, in make_template_context
    admin = Admin.query.first()
            ^^^^^^^^^^^
  File "E:\works\hyyb\.venv\Lib\site-packages\flask_sqlalchemy\__init__.py", line 517, in __get__
    mapper = orm.class_mapper(type)
             ^^^^^^^^^^^^^^^^^^^^^^
  File "E:\works\hyyb\.venv\Lib\site-packages\sqlalchemy\orm\base.py", line 444, in class_mapper
    mapper = _inspect_mapped_class(class_, configure=configure)
             ^^^^^^^^^^^^^^^^^^^^^^^^^^^^^^^^^^^^^^^^^^^^^^^^^^
  File "E:\works\hyyb\.venv\Lib\site-packages\sqlalchemy\orm\base.py", line 423, in _inspect_mapped_class
    mapper._configure_all()
  File "E:\works\hyyb\.venv\Lib\site-packages\sqlalchemy\orm\mapper.py", line 1337, in _configure_all
    configure_mappers()
  File "E:\works\hyyb\.venv\Lib\site-packages\sqlalchemy\orm\mapper.py", line 3255, in configure_mappers
    mapper._post_configure_properties()
  File "E:\works\hyyb\.venv\Lib\site-packages\sqlalchemy\orm\mapper.py", line 1950, in _post_configure_properties
    prop.init()
  File "E:\works\hyyb\.venv\Lib\site-packages\sqlalchemy\orm\interfaces.py", line 196, in init
    self.do_init()
  File "E:\works\hyyb\.venv\Lib\site-packages\sqlalchemy\orm\relationships.py", line 1936, in do_init
    self._setup_join_conditions()
  File "E:\works\hyyb\.venv\Lib\site-packages\sqlalchemy\orm\relationships.py", line 2000, in _setup_join_conditions
    self._join_condition = jc = JoinCondition(
                                ^^^^^^^^^^^^^^
  File "E:\works\hyyb\.venv\Lib\site-packages\sqlalchemy\orm\relationships.py", line 2360, in __init__
    self._determine_joins()
  File "E:\works\hyyb\.venv\Lib\site-packages\sqlalchemy\orm\relationships.py", line 2493, in _determine_joins
    util.raise_(
  File "E:\works\hyyb\.venv\Lib\site-packages\sqlalchemy\util\compat.py", line 178, in raise_
    raise exception
sqlalchemy.exc.NoForeignKeysError: Could not determine join condition between parent/child tables on relationship Stuff.attendances - there are no foreign keys linking these tables.  Ensure that referencing columns are associated with a ForeignKey or ForeignKeyConstraint, or specify a 'primaryjoin' expression.
2025-04-15 14:18:42,059 - hyyb - ERROR - Exception on /auth/login [GET]
Traceback (most recent call last):
  File "E:\works\hyyb\.venv\Lib\site-packages\flask\app.py", line 2447, in wsgi_app
    response = self.full_dispatch_request()
               ^^^^^^^^^^^^^^^^^^^^^^^^^^^^
  File "E:\works\hyyb\.venv\Lib\site-packages\flask\app.py", line 1952, in full_dispatch_request
    rv = self.handle_user_exception(e)
         ^^^^^^^^^^^^^^^^^^^^^^^^^^^^^
  File "E:\works\hyyb\.venv\Lib\site-packages\flask\app.py", line 1821, in handle_user_exception
    reraise(exc_type, exc_value, tb)
  File "E:\works\hyyb\.venv\Lib\site-packages\flask\_compat.py", line 39, in reraise
    raise value
  File "E:\works\hyyb\.venv\Lib\site-packages\flask\app.py", line 1950, in full_dispatch_request
    rv = self.dispatch_request()
         ^^^^^^^^^^^^^^^^^^^^^^^
  File "E:\works\hyyb\.venv\Lib\site-packages\flask\app.py", line 1936, in dispatch_request
    return self.view_functions[rule.endpoint](**req.view_args)
           ^^^^^^^^^^^^^^^^^^^^^^^^^^^^^^^^^^^^^^^^^^^^^^^^^^^
  File "E:\works\hyyb\hyyb\blueprints\auth.py", line 35, in login
    return render_template('auth/login.html', form=form) #
           ^^^^^^^^^^^^^^^^^^^^^^^^^^^^^^^^^^^^^^^^^^^^^
  File "E:\works\hyyb\.venv\Lib\site-packages\flask\templating.py", line 136, in render_template
    ctx.app.update_template_context(context)
  File "E:\works\hyyb\.venv\Lib\site-packages\flask\app.py", line 838, in update_template_context
    context.update(func())
                   ^^^^^^
  File "E:\works\hyyb\hyyb\__init__.py", line 111, in make_template_context
    admin = Admin.query.first()
            ^^^^^^^^^^^
  File "E:\works\hyyb\.venv\Lib\site-packages\flask_sqlalchemy\__init__.py", line 517, in __get__
    mapper = orm.class_mapper(type)
             ^^^^^^^^^^^^^^^^^^^^^^
  File "E:\works\hyyb\.venv\Lib\site-packages\sqlalchemy\orm\base.py", line 444, in class_mapper
    mapper = _inspect_mapped_class(class_, configure=configure)
             ^^^^^^^^^^^^^^^^^^^^^^^^^^^^^^^^^^^^^^^^^^^^^^^^^^
  File "E:\works\hyyb\.venv\Lib\site-packages\sqlalchemy\orm\base.py", line 423, in _inspect_mapped_class
    mapper._configure_all()
  File "E:\works\hyyb\.venv\Lib\site-packages\sqlalchemy\orm\mapper.py", line 1337, in _configure_all
    configure_mappers()
  File "E:\works\hyyb\.venv\Lib\site-packages\sqlalchemy\orm\mapper.py", line 3251, in configure_mappers
    raise e
sqlalchemy.exc.InvalidRequestError: One or more mappers failed to initialize - can't proceed with initialization of other mappers. Triggering mapper: 'mapped class Stuff->stuff'. Original exception was: Could not determine join condition between parent/child tables on relationship Stuff.attendances - there are no foreign keys linking these tables.  Ensure that referencing columns are associated with a ForeignKey or ForeignKeyConstraint, or specify a 'primaryjoin' expression.
2025-04-15 14:18:42,175 - hyyb - ERROR - Exception on /favicon.ico [GET]
Traceback (most recent call last):
  File "E:\works\hyyb\.venv\Lib\site-packages\flask\app.py", line 1950, in full_dispatch_request
    rv = self.dispatch_request()
         ^^^^^^^^^^^^^^^^^^^^^^^
  File "E:\works\hyyb\.venv\Lib\site-packages\flask\app.py", line 1926, in dispatch_request
    self.raise_routing_exception(req)
  File "E:\works\hyyb\.venv\Lib\site-packages\flask\app.py", line 1908, in raise_routing_exception
    raise request.routing_exception
  File "E:\works\hyyb\.venv\Lib\site-packages\flask\ctx.py", line 350, in match_request
    result = self.url_adapter.match(return_rule=True)
             ^^^^^^^^^^^^^^^^^^^^^^^^^^^^^^^^^^^^^^^^
  File "E:\works\hyyb\.venv\Lib\site-packages\werkzeug\routing.py", line 1945, in match
    raise NotFound()
werkzeug.exceptions.NotFound: 404 Not Found: The requested URL was not found on the server. If you entered the URL manually please check your spelling and try again.

During handling of the above exception, another exception occurred:

Traceback (most recent call last):
  File "E:\works\hyyb\.venv\Lib\site-packages\flask\app.py", line 2447, in wsgi_app
    response = self.full_dispatch_request()
               ^^^^^^^^^^^^^^^^^^^^^^^^^^^^
  File "E:\works\hyyb\.venv\Lib\site-packages\flask\app.py", line 1952, in full_dispatch_request
    rv = self.handle_user_exception(e)
         ^^^^^^^^^^^^^^^^^^^^^^^^^^^^^
  File "E:\works\hyyb\.venv\Lib\site-packages\flask\app.py", line 1816, in handle_user_exception
    return self.handle_http_exception(e)
           ^^^^^^^^^^^^^^^^^^^^^^^^^^^^^
  File "E:\works\hyyb\.venv\Lib\site-packages\flask\app.py", line 1744, in handle_http_exception
    return handler(e)
           ^^^^^^^^^^
  File "E:\works\hyyb\hyyb\__init__.py", line 144, in page_not_found
    return render_template('errors/404.html'), 404
           ^^^^^^^^^^^^^^^^^^^^^^^^^^^^^^^^^^
  File "E:\works\hyyb\.venv\Lib\site-packages\flask\templating.py", line 136, in render_template
    ctx.app.update_template_context(context)
  File "E:\works\hyyb\.venv\Lib\site-packages\flask\app.py", line 838, in update_template_context
    context.update(func())
                   ^^^^^^
  File "E:\works\hyyb\hyyb\__init__.py", line 111, in make_template_context
    admin = Admin.query.first()
            ^^^^^^^^^^^
  File "E:\works\hyyb\.venv\Lib\site-packages\flask_sqlalchemy\__init__.py", line 517, in __get__
    mapper = orm.class_mapper(type)
             ^^^^^^^^^^^^^^^^^^^^^^
  File "E:\works\hyyb\.venv\Lib\site-packages\sqlalchemy\orm\base.py", line 444, in class_mapper
    mapper = _inspect_mapped_class(class_, configure=configure)
             ^^^^^^^^^^^^^^^^^^^^^^^^^^^^^^^^^^^^^^^^^^^^^^^^^^
  File "E:\works\hyyb\.venv\Lib\site-packages\sqlalchemy\orm\base.py", line 423, in _inspect_mapped_class
    mapper._configure_all()
  File "E:\works\hyyb\.venv\Lib\site-packages\sqlalchemy\orm\mapper.py", line 1337, in _configure_all
    configure_mappers()
  File "E:\works\hyyb\.venv\Lib\site-packages\sqlalchemy\orm\mapper.py", line 3251, in configure_mappers
    raise e
sqlalchemy.exc.InvalidRequestError: One or more mappers failed to initialize - can't proceed with initialization of other mappers. Triggering mapper: 'mapped class Stuff->stuff'. Original exception was: Could not determine join condition between parent/child tables on relationship Stuff.attendances - there are no foreign keys linking these tables.  Ensure that referencing columns are associated with a ForeignKey or ForeignKeyConstraint, or specify a 'primaryjoin' expression.
2025-04-15 14:18:42,285 - hyyb - ERROR - Exception on /favicon.ico [GET]
Traceback (most recent call last):
  File "E:\works\hyyb\.venv\Lib\site-packages\flask\app.py", line 1950, in full_dispatch_request
    rv = self.dispatch_request()
         ^^^^^^^^^^^^^^^^^^^^^^^
  File "E:\works\hyyb\.venv\Lib\site-packages\flask\app.py", line 1926, in dispatch_request
    self.raise_routing_exception(req)
  File "E:\works\hyyb\.venv\Lib\site-packages\flask\app.py", line 1908, in raise_routing_exception
    raise request.routing_exception
  File "E:\works\hyyb\.venv\Lib\site-packages\flask\ctx.py", line 350, in match_request
    result = self.url_adapter.match(return_rule=True)
             ^^^^^^^^^^^^^^^^^^^^^^^^^^^^^^^^^^^^^^^^
  File "E:\works\hyyb\.venv\Lib\site-packages\werkzeug\routing.py", line 1945, in match
    raise NotFound()
werkzeug.exceptions.NotFound: 404 Not Found: The requested URL was not found on the server. If you entered the URL manually please check your spelling and try again.

During handling of the above exception, another exception occurred:

Traceback (most recent call last):
  File "E:\works\hyyb\.venv\Lib\site-packages\flask\app.py", line 2447, in wsgi_app
    response = self.full_dispatch_request()
               ^^^^^^^^^^^^^^^^^^^^^^^^^^^^
  File "E:\works\hyyb\.venv\Lib\site-packages\flask\app.py", line 1952, in full_dispatch_request
    rv = self.handle_user_exception(e)
         ^^^^^^^^^^^^^^^^^^^^^^^^^^^^^
  File "E:\works\hyyb\.venv\Lib\site-packages\flask\app.py", line 1816, in handle_user_exception
    return self.handle_http_exception(e)
           ^^^^^^^^^^^^^^^^^^^^^^^^^^^^^
  File "E:\works\hyyb\.venv\Lib\site-packages\flask\app.py", line 1744, in handle_http_exception
    return handler(e)
           ^^^^^^^^^^
  File "E:\works\hyyb\hyyb\__init__.py", line 144, in page_not_found
    return render_template('errors/404.html'), 404
           ^^^^^^^^^^^^^^^^^^^^^^^^^^^^^^^^^^
  File "E:\works\hyyb\.venv\Lib\site-packages\flask\templating.py", line 136, in render_template
    ctx.app.update_template_context(context)
  File "E:\works\hyyb\.venv\Lib\site-packages\flask\app.py", line 838, in update_template_context
    context.update(func())
                   ^^^^^^
  File "E:\works\hyyb\hyyb\__init__.py", line 111, in make_template_context
    admin = Admin.query.first()
            ^^^^^^^^^^^
  File "E:\works\hyyb\.venv\Lib\site-packages\flask_sqlalchemy\__init__.py", line 517, in __get__
    mapper = orm.class_mapper(type)
             ^^^^^^^^^^^^^^^^^^^^^^
  File "E:\works\hyyb\.venv\Lib\site-packages\sqlalchemy\orm\base.py", line 444, in class_mapper
    mapper = _inspect_mapped_class(class_, configure=configure)
             ^^^^^^^^^^^^^^^^^^^^^^^^^^^^^^^^^^^^^^^^^^^^^^^^^^
  File "E:\works\hyyb\.venv\Lib\site-packages\sqlalchemy\orm\base.py", line 423, in _inspect_mapped_class
    mapper._configure_all()
  File "E:\works\hyyb\.venv\Lib\site-packages\sqlalchemy\orm\mapper.py", line 1337, in _configure_all
    configure_mappers()
  File "E:\works\hyyb\.venv\Lib\site-packages\sqlalchemy\orm\mapper.py", line 3251, in configure_mappers
    raise e
sqlalchemy.exc.InvalidRequestError: One or more mappers failed to initialize - can't proceed with initialization of other mappers. Triggering mapper: 'mapped class Stuff->stuff'. Original exception was: Could not determine join condition between parent/child tables on relationship Stuff.attendances - there are no foreign keys linking these tables.  Ensure that referencing columns are associated with a ForeignKey or ForeignKeyConstraint, or specify a 'primaryjoin' expression.
2025-04-15 14:19:51,223 - hyyb - ERROR - Exception on /auth/login [GET]
Traceback (most recent call last):
  File "E:\works\hyyb\.venv\Lib\site-packages\sqlalchemy\orm\relationships.py", line 2471, in _determine_joins
    self.primaryjoin = join_condition(
                       ^^^^^^^^^^^^^^^
  File "<string>", line 2, in join_condition
  File "<string>", line 2, in _join_condition
  File "E:\works\hyyb\.venv\Lib\site-packages\sqlalchemy\util\deprecations.py", line 128, in warned
    return fn(*args, **kwargs)
           ^^^^^^^^^^^^^^^^^^^
  File "E:\works\hyyb\.venv\Lib\site-packages\sqlalchemy\sql\selectable.py", line 949, in _join_condition
    raise exc.NoForeignKeysError(
sqlalchemy.exc.NoForeignKeysError: Can't find any foreign key relationships between 'stuff' and 'attendance'.

The above exception was the direct cause of the following exception:

Traceback (most recent call last):
  File "E:\works\hyyb\.venv\Lib\site-packages\flask\app.py", line 2447, in wsgi_app
    response = self.full_dispatch_request()
               ^^^^^^^^^^^^^^^^^^^^^^^^^^^^
  File "E:\works\hyyb\.venv\Lib\site-packages\flask\app.py", line 1952, in full_dispatch_request
    rv = self.handle_user_exception(e)
         ^^^^^^^^^^^^^^^^^^^^^^^^^^^^^
  File "E:\works\hyyb\.venv\Lib\site-packages\flask\app.py", line 1821, in handle_user_exception
    reraise(exc_type, exc_value, tb)
  File "E:\works\hyyb\.venv\Lib\site-packages\flask\_compat.py", line 39, in reraise
    raise value
  File "E:\works\hyyb\.venv\Lib\site-packages\flask\app.py", line 1950, in full_dispatch_request
    rv = self.dispatch_request()
         ^^^^^^^^^^^^^^^^^^^^^^^
  File "E:\works\hyyb\.venv\Lib\site-packages\flask\app.py", line 1936, in dispatch_request
    return self.view_functions[rule.endpoint](**req.view_args)
           ^^^^^^^^^^^^^^^^^^^^^^^^^^^^^^^^^^^^^^^^^^^^^^^^^^^
  File "E:\works\hyyb\hyyb\blueprints\auth.py", line 35, in login
    return render_template('auth/login.html', form=form) #
           ^^^^^^^^^^^^^^^^^^^^^^^^^^^^^^^^^^^^^^^^^^^^^
  File "E:\works\hyyb\.venv\Lib\site-packages\flask\templating.py", line 136, in render_template
    ctx.app.update_template_context(context)
  File "E:\works\hyyb\.venv\Lib\site-packages\flask\app.py", line 838, in update_template_context
    context.update(func())
                   ^^^^^^
  File "E:\works\hyyb\hyyb\__init__.py", line 111, in make_template_context
    admin = Admin.query.first()
            ^^^^^^^^^^^
  File "E:\works\hyyb\.venv\Lib\site-packages\flask_sqlalchemy\__init__.py", line 517, in __get__
    mapper = orm.class_mapper(type)
             ^^^^^^^^^^^^^^^^^^^^^^
  File "E:\works\hyyb\.venv\Lib\site-packages\sqlalchemy\orm\base.py", line 444, in class_mapper
    mapper = _inspect_mapped_class(class_, configure=configure)
             ^^^^^^^^^^^^^^^^^^^^^^^^^^^^^^^^^^^^^^^^^^^^^^^^^^
  File "E:\works\hyyb\.venv\Lib\site-packages\sqlalchemy\orm\base.py", line 423, in _inspect_mapped_class
    mapper._configure_all()
  File "E:\works\hyyb\.venv\Lib\site-packages\sqlalchemy\orm\mapper.py", line 1337, in _configure_all
    configure_mappers()
  File "E:\works\hyyb\.venv\Lib\site-packages\sqlalchemy\orm\mapper.py", line 3255, in configure_mappers
    mapper._post_configure_properties()
  File "E:\works\hyyb\.venv\Lib\site-packages\sqlalchemy\orm\mapper.py", line 1950, in _post_configure_properties
    prop.init()
  File "E:\works\hyyb\.venv\Lib\site-packages\sqlalchemy\orm\interfaces.py", line 196, in init
    self.do_init()
  File "E:\works\hyyb\.venv\Lib\site-packages\sqlalchemy\orm\relationships.py", line 1936, in do_init
    self._setup_join_conditions()
  File "E:\works\hyyb\.venv\Lib\site-packages\sqlalchemy\orm\relationships.py", line 2000, in _setup_join_conditions
    self._join_condition = jc = JoinCondition(
                                ^^^^^^^^^^^^^^
  File "E:\works\hyyb\.venv\Lib\site-packages\sqlalchemy\orm\relationships.py", line 2360, in __init__
    self._determine_joins()
  File "E:\works\hyyb\.venv\Lib\site-packages\sqlalchemy\orm\relationships.py", line 2493, in _determine_joins
    util.raise_(
  File "E:\works\hyyb\.venv\Lib\site-packages\sqlalchemy\util\compat.py", line 178, in raise_
    raise exception
sqlalchemy.exc.NoForeignKeysError: Could not determine join condition between parent/child tables on relationship Stuff.attendances - there are no foreign keys linking these tables.  Ensure that referencing columns are associated with a ForeignKey or ForeignKeyConstraint, or specify a 'primaryjoin' expression.
2025-04-15 14:19:51,362 - hyyb - ERROR - Exception on /auth/login [GET]
Traceback (most recent call last):
  File "E:\works\hyyb\.venv\Lib\site-packages\flask\app.py", line 2447, in wsgi_app
    response = self.full_dispatch_request()
               ^^^^^^^^^^^^^^^^^^^^^^^^^^^^
  File "E:\works\hyyb\.venv\Lib\site-packages\flask\app.py", line 1952, in full_dispatch_request
    rv = self.handle_user_exception(e)
         ^^^^^^^^^^^^^^^^^^^^^^^^^^^^^
  File "E:\works\hyyb\.venv\Lib\site-packages\flask\app.py", line 1821, in handle_user_exception
    reraise(exc_type, exc_value, tb)
  File "E:\works\hyyb\.venv\Lib\site-packages\flask\_compat.py", line 39, in reraise
    raise value
  File "E:\works\hyyb\.venv\Lib\site-packages\flask\app.py", line 1950, in full_dispatch_request
    rv = self.dispatch_request()
         ^^^^^^^^^^^^^^^^^^^^^^^
  File "E:\works\hyyb\.venv\Lib\site-packages\flask\app.py", line 1936, in dispatch_request
    return self.view_functions[rule.endpoint](**req.view_args)
           ^^^^^^^^^^^^^^^^^^^^^^^^^^^^^^^^^^^^^^^^^^^^^^^^^^^
  File "E:\works\hyyb\hyyb\blueprints\auth.py", line 35, in login
    return render_template('auth/login.html', form=form) #
           ^^^^^^^^^^^^^^^^^^^^^^^^^^^^^^^^^^^^^^^^^^^^^
  File "E:\works\hyyb\.venv\Lib\site-packages\flask\templating.py", line 136, in render_template
    ctx.app.update_template_context(context)
  File "E:\works\hyyb\.venv\Lib\site-packages\flask\app.py", line 838, in update_template_context
    context.update(func())
                   ^^^^^^
  File "E:\works\hyyb\hyyb\__init__.py", line 111, in make_template_context
    admin = Admin.query.first()
            ^^^^^^^^^^^
  File "E:\works\hyyb\.venv\Lib\site-packages\flask_sqlalchemy\__init__.py", line 517, in __get__
    mapper = orm.class_mapper(type)
             ^^^^^^^^^^^^^^^^^^^^^^
  File "E:\works\hyyb\.venv\Lib\site-packages\sqlalchemy\orm\base.py", line 444, in class_mapper
    mapper = _inspect_mapped_class(class_, configure=configure)
             ^^^^^^^^^^^^^^^^^^^^^^^^^^^^^^^^^^^^^^^^^^^^^^^^^^
  File "E:\works\hyyb\.venv\Lib\site-packages\sqlalchemy\orm\base.py", line 423, in _inspect_mapped_class
    mapper._configure_all()
  File "E:\works\hyyb\.venv\Lib\site-packages\sqlalchemy\orm\mapper.py", line 1337, in _configure_all
    configure_mappers()
  File "E:\works\hyyb\.venv\Lib\site-packages\sqlalchemy\orm\mapper.py", line 3251, in configure_mappers
    raise e
sqlalchemy.exc.InvalidRequestError: One or more mappers failed to initialize - can't proceed with initialization of other mappers. Triggering mapper: 'mapped class Stuff->stuff'. Original exception was: Could not determine join condition between parent/child tables on relationship Stuff.attendances - there are no foreign keys linking these tables.  Ensure that referencing columns are associated with a ForeignKey or ForeignKeyConstraint, or specify a 'primaryjoin' expression.
2025-04-15 14:19:51,457 - hyyb - ERROR - Exception on /favicon.ico [GET]
Traceback (most recent call last):
  File "E:\works\hyyb\.venv\Lib\site-packages\flask\app.py", line 1950, in full_dispatch_request
    rv = self.dispatch_request()
         ^^^^^^^^^^^^^^^^^^^^^^^
  File "E:\works\hyyb\.venv\Lib\site-packages\flask\app.py", line 1926, in dispatch_request
    self.raise_routing_exception(req)
  File "E:\works\hyyb\.venv\Lib\site-packages\flask\app.py", line 1908, in raise_routing_exception
    raise request.routing_exception
  File "E:\works\hyyb\.venv\Lib\site-packages\flask\ctx.py", line 350, in match_request
    result = self.url_adapter.match(return_rule=True)
             ^^^^^^^^^^^^^^^^^^^^^^^^^^^^^^^^^^^^^^^^
  File "E:\works\hyyb\.venv\Lib\site-packages\werkzeug\routing.py", line 1945, in match
    raise NotFound()
werkzeug.exceptions.NotFound: 404 Not Found: The requested URL was not found on the server. If you entered the URL manually please check your spelling and try again.

During handling of the above exception, another exception occurred:

Traceback (most recent call last):
  File "E:\works\hyyb\.venv\Lib\site-packages\flask\app.py", line 2447, in wsgi_app
    response = self.full_dispatch_request()
               ^^^^^^^^^^^^^^^^^^^^^^^^^^^^
  File "E:\works\hyyb\.venv\Lib\site-packages\flask\app.py", line 1952, in full_dispatch_request
    rv = self.handle_user_exception(e)
         ^^^^^^^^^^^^^^^^^^^^^^^^^^^^^
  File "E:\works\hyyb\.venv\Lib\site-packages\flask\app.py", line 1816, in handle_user_exception
    return self.handle_http_exception(e)
           ^^^^^^^^^^^^^^^^^^^^^^^^^^^^^
  File "E:\works\hyyb\.venv\Lib\site-packages\flask\app.py", line 1744, in handle_http_exception
    return handler(e)
           ^^^^^^^^^^
  File "E:\works\hyyb\hyyb\__init__.py", line 144, in page_not_found
    return render_template('errors/404.html'), 404
           ^^^^^^^^^^^^^^^^^^^^^^^^^^^^^^^^^^
  File "E:\works\hyyb\.venv\Lib\site-packages\flask\templating.py", line 136, in render_template
    ctx.app.update_template_context(context)
  File "E:\works\hyyb\.venv\Lib\site-packages\flask\app.py", line 838, in update_template_context
    context.update(func())
                   ^^^^^^
  File "E:\works\hyyb\hyyb\__init__.py", line 111, in make_template_context
    admin = Admin.query.first()
            ^^^^^^^^^^^
  File "E:\works\hyyb\.venv\Lib\site-packages\flask_sqlalchemy\__init__.py", line 517, in __get__
    mapper = orm.class_mapper(type)
             ^^^^^^^^^^^^^^^^^^^^^^
  File "E:\works\hyyb\.venv\Lib\site-packages\sqlalchemy\orm\base.py", line 444, in class_mapper
    mapper = _inspect_mapped_class(class_, configure=configure)
             ^^^^^^^^^^^^^^^^^^^^^^^^^^^^^^^^^^^^^^^^^^^^^^^^^^
  File "E:\works\hyyb\.venv\Lib\site-packages\sqlalchemy\orm\base.py", line 423, in _inspect_mapped_class
    mapper._configure_all()
  File "E:\works\hyyb\.venv\Lib\site-packages\sqlalchemy\orm\mapper.py", line 1337, in _configure_all
    configure_mappers()
  File "E:\works\hyyb\.venv\Lib\site-packages\sqlalchemy\orm\mapper.py", line 3251, in configure_mappers
    raise e
sqlalchemy.exc.InvalidRequestError: One or more mappers failed to initialize - can't proceed with initialization of other mappers. Triggering mapper: 'mapped class Stuff->stuff'. Original exception was: Could not determine join condition between parent/child tables on relationship Stuff.attendances - there are no foreign keys linking these tables.  Ensure that referencing columns are associated with a ForeignKey or ForeignKeyConstraint, or specify a 'primaryjoin' expression.
2025-04-15 14:19:51,501 - hyyb - ERROR - Exception on /favicon.ico [GET]
Traceback (most recent call last):
  File "E:\works\hyyb\.venv\Lib\site-packages\flask\app.py", line 1950, in full_dispatch_request
    rv = self.dispatch_request()
         ^^^^^^^^^^^^^^^^^^^^^^^
  File "E:\works\hyyb\.venv\Lib\site-packages\flask\app.py", line 1926, in dispatch_request
    self.raise_routing_exception(req)
  File "E:\works\hyyb\.venv\Lib\site-packages\flask\app.py", line 1908, in raise_routing_exception
    raise request.routing_exception
  File "E:\works\hyyb\.venv\Lib\site-packages\flask\ctx.py", line 350, in match_request
    result = self.url_adapter.match(return_rule=True)
             ^^^^^^^^^^^^^^^^^^^^^^^^^^^^^^^^^^^^^^^^
  File "E:\works\hyyb\.venv\Lib\site-packages\werkzeug\routing.py", line 1945, in match
    raise NotFound()
werkzeug.exceptions.NotFound: 404 Not Found: The requested URL was not found on the server. If you entered the URL manually please check your spelling and try again.

During handling of the above exception, another exception occurred:

Traceback (most recent call last):
  File "E:\works\hyyb\.venv\Lib\site-packages\flask\app.py", line 2447, in wsgi_app
    response = self.full_dispatch_request()
               ^^^^^^^^^^^^^^^^^^^^^^^^^^^^
  File "E:\works\hyyb\.venv\Lib\site-packages\flask\app.py", line 1952, in full_dispatch_request
    rv = self.handle_user_exception(e)
         ^^^^^^^^^^^^^^^^^^^^^^^^^^^^^
  File "E:\works\hyyb\.venv\Lib\site-packages\flask\app.py", line 1816, in handle_user_exception
    return self.handle_http_exception(e)
           ^^^^^^^^^^^^^^^^^^^^^^^^^^^^^
  File "E:\works\hyyb\.venv\Lib\site-packages\flask\app.py", line 1744, in handle_http_exception
    return handler(e)
           ^^^^^^^^^^
  File "E:\works\hyyb\hyyb\__init__.py", line 144, in page_not_found
    return render_template('errors/404.html'), 404
           ^^^^^^^^^^^^^^^^^^^^^^^^^^^^^^^^^^
  File "E:\works\hyyb\.venv\Lib\site-packages\flask\templating.py", line 136, in render_template
    ctx.app.update_template_context(context)
  File "E:\works\hyyb\.venv\Lib\site-packages\flask\app.py", line 838, in update_template_context
    context.update(func())
                   ^^^^^^
  File "E:\works\hyyb\hyyb\__init__.py", line 111, in make_template_context
    admin = Admin.query.first()
            ^^^^^^^^^^^
  File "E:\works\hyyb\.venv\Lib\site-packages\flask_sqlalchemy\__init__.py", line 517, in __get__
    mapper = orm.class_mapper(type)
             ^^^^^^^^^^^^^^^^^^^^^^
  File "E:\works\hyyb\.venv\Lib\site-packages\sqlalchemy\orm\base.py", line 444, in class_mapper
    mapper = _inspect_mapped_class(class_, configure=configure)
             ^^^^^^^^^^^^^^^^^^^^^^^^^^^^^^^^^^^^^^^^^^^^^^^^^^
  File "E:\works\hyyb\.venv\Lib\site-packages\sqlalchemy\orm\base.py", line 423, in _inspect_mapped_class
    mapper._configure_all()
  File "E:\works\hyyb\.venv\Lib\site-packages\sqlalchemy\orm\mapper.py", line 1337, in _configure_all
    configure_mappers()
  File "E:\works\hyyb\.venv\Lib\site-packages\sqlalchemy\orm\mapper.py", line 3251, in configure_mappers
    raise e
sqlalchemy.exc.InvalidRequestError: One or more mappers failed to initialize - can't proceed with initialization of other mappers. Triggering mapper: 'mapped class Stuff->stuff'. Original exception was: Could not determine join condition between parent/child tables on relationship Stuff.attendances - there are no foreign keys linking these tables.  Ensure that referencing columns are associated with a ForeignKey or ForeignKeyConstraint, or specify a 'primaryjoin' expression.
2025-04-15 14:33:09,505 - hyyb - ERROR - Exception on /auth/login [GET]
Traceback (most recent call last):
  File "E:\works\hyyb\.venv\Lib\site-packages\sqlalchemy\orm\relationships.py", line 2471, in _determine_joins
    self.primaryjoin = join_condition(
                       ^^^^^^^^^^^^^^^
  File "<string>", line 2, in join_condition
  File "<string>", line 2, in _join_condition
  File "E:\works\hyyb\.venv\Lib\site-packages\sqlalchemy\util\deprecations.py", line 128, in warned
    return fn(*args, **kwargs)
           ^^^^^^^^^^^^^^^^^^^
  File "E:\works\hyyb\.venv\Lib\site-packages\sqlalchemy\sql\selectable.py", line 949, in _join_condition
    raise exc.NoForeignKeysError(
sqlalchemy.exc.NoForeignKeysError: Can't find any foreign key relationships between 'stuff' and 'attendance'.

The above exception was the direct cause of the following exception:

Traceback (most recent call last):
  File "E:\works\hyyb\.venv\Lib\site-packages\flask\app.py", line 2447, in wsgi_app
    response = self.full_dispatch_request()
               ^^^^^^^^^^^^^^^^^^^^^^^^^^^^
  File "E:\works\hyyb\.venv\Lib\site-packages\flask\app.py", line 1952, in full_dispatch_request
    rv = self.handle_user_exception(e)
         ^^^^^^^^^^^^^^^^^^^^^^^^^^^^^
  File "E:\works\hyyb\.venv\Lib\site-packages\flask\app.py", line 1821, in handle_user_exception
    reraise(exc_type, exc_value, tb)
  File "E:\works\hyyb\.venv\Lib\site-packages\flask\_compat.py", line 39, in reraise
    raise value
  File "E:\works\hyyb\.venv\Lib\site-packages\flask\app.py", line 1950, in full_dispatch_request
    rv = self.dispatch_request()
         ^^^^^^^^^^^^^^^^^^^^^^^
  File "E:\works\hyyb\.venv\Lib\site-packages\flask\app.py", line 1936, in dispatch_request
    return self.view_functions[rule.endpoint](**req.view_args)
           ^^^^^^^^^^^^^^^^^^^^^^^^^^^^^^^^^^^^^^^^^^^^^^^^^^^
  File "E:\works\hyyb\hyyb\blueprints\auth.py", line 35, in login
    return render_template('auth/login.html', form=form) #
           ^^^^^^^^^^^^^^^^^^^^^^^^^^^^^^^^^^^^^^^^^^^^^
  File "E:\works\hyyb\.venv\Lib\site-packages\flask\templating.py", line 136, in render_template
    ctx.app.update_template_context(context)
  File "E:\works\hyyb\.venv\Lib\site-packages\flask\app.py", line 838, in update_template_context
    context.update(func())
                   ^^^^^^
  File "E:\works\hyyb\hyyb\__init__.py", line 111, in make_template_context
    admin = Admin.query.first()
            ^^^^^^^^^^^
  File "E:\works\hyyb\.venv\Lib\site-packages\flask_sqlalchemy\__init__.py", line 517, in __get__
    mapper = orm.class_mapper(type)
             ^^^^^^^^^^^^^^^^^^^^^^
  File "E:\works\hyyb\.venv\Lib\site-packages\sqlalchemy\orm\base.py", line 444, in class_mapper
    mapper = _inspect_mapped_class(class_, configure=configure)
             ^^^^^^^^^^^^^^^^^^^^^^^^^^^^^^^^^^^^^^^^^^^^^^^^^^
  File "E:\works\hyyb\.venv\Lib\site-packages\sqlalchemy\orm\base.py", line 423, in _inspect_mapped_class
    mapper._configure_all()
  File "E:\works\hyyb\.venv\Lib\site-packages\sqlalchemy\orm\mapper.py", line 1337, in _configure_all
    configure_mappers()
  File "E:\works\hyyb\.venv\Lib\site-packages\sqlalchemy\orm\mapper.py", line 3255, in configure_mappers
    mapper._post_configure_properties()
  File "E:\works\hyyb\.venv\Lib\site-packages\sqlalchemy\orm\mapper.py", line 1950, in _post_configure_properties
    prop.init()
  File "E:\works\hyyb\.venv\Lib\site-packages\sqlalchemy\orm\interfaces.py", line 196, in init
    self.do_init()
  File "E:\works\hyyb\.venv\Lib\site-packages\sqlalchemy\orm\relationships.py", line 1936, in do_init
    self._setup_join_conditions()
  File "E:\works\hyyb\.venv\Lib\site-packages\sqlalchemy\orm\relationships.py", line 2000, in _setup_join_conditions
    self._join_condition = jc = JoinCondition(
                                ^^^^^^^^^^^^^^
  File "E:\works\hyyb\.venv\Lib\site-packages\sqlalchemy\orm\relationships.py", line 2360, in __init__
    self._determine_joins()
  File "E:\works\hyyb\.venv\Lib\site-packages\sqlalchemy\orm\relationships.py", line 2493, in _determine_joins
    util.raise_(
  File "E:\works\hyyb\.venv\Lib\site-packages\sqlalchemy\util\compat.py", line 178, in raise_
    raise exception
sqlalchemy.exc.NoForeignKeysError: Could not determine join condition between parent/child tables on relationship Stuff.attendances - there are no foreign keys linking these tables.  Ensure that referencing columns are associated with a ForeignKey or ForeignKeyConstraint, or specify a 'primaryjoin' expression.
2025-04-15 14:33:09,665 - hyyb - ERROR - Exception on /auth/login [GET]
Traceback (most recent call last):
  File "E:\works\hyyb\.venv\Lib\site-packages\flask\app.py", line 2447, in wsgi_app
    response = self.full_dispatch_request()
               ^^^^^^^^^^^^^^^^^^^^^^^^^^^^
  File "E:\works\hyyb\.venv\Lib\site-packages\flask\app.py", line 1952, in full_dispatch_request
    rv = self.handle_user_exception(e)
         ^^^^^^^^^^^^^^^^^^^^^^^^^^^^^
  File "E:\works\hyyb\.venv\Lib\site-packages\flask\app.py", line 1821, in handle_user_exception
    reraise(exc_type, exc_value, tb)
  File "E:\works\hyyb\.venv\Lib\site-packages\flask\_compat.py", line 39, in reraise
    raise value
  File "E:\works\hyyb\.venv\Lib\site-packages\flask\app.py", line 1950, in full_dispatch_request
    rv = self.dispatch_request()
         ^^^^^^^^^^^^^^^^^^^^^^^
  File "E:\works\hyyb\.venv\Lib\site-packages\flask\app.py", line 1936, in dispatch_request
    return self.view_functions[rule.endpoint](**req.view_args)
           ^^^^^^^^^^^^^^^^^^^^^^^^^^^^^^^^^^^^^^^^^^^^^^^^^^^
  File "E:\works\hyyb\hyyb\blueprints\auth.py", line 35, in login
    return render_template('auth/login.html', form=form) #
           ^^^^^^^^^^^^^^^^^^^^^^^^^^^^^^^^^^^^^^^^^^^^^
  File "E:\works\hyyb\.venv\Lib\site-packages\flask\templating.py", line 136, in render_template
    ctx.app.update_template_context(context)
  File "E:\works\hyyb\.venv\Lib\site-packages\flask\app.py", line 838, in update_template_context
    context.update(func())
                   ^^^^^^
  File "E:\works\hyyb\hyyb\__init__.py", line 111, in make_template_context
    admin = Admin.query.first()
            ^^^^^^^^^^^
  File "E:\works\hyyb\.venv\Lib\site-packages\flask_sqlalchemy\__init__.py", line 517, in __get__
    mapper = orm.class_mapper(type)
             ^^^^^^^^^^^^^^^^^^^^^^
  File "E:\works\hyyb\.venv\Lib\site-packages\sqlalchemy\orm\base.py", line 444, in class_mapper
    mapper = _inspect_mapped_class(class_, configure=configure)
             ^^^^^^^^^^^^^^^^^^^^^^^^^^^^^^^^^^^^^^^^^^^^^^^^^^
  File "E:\works\hyyb\.venv\Lib\site-packages\sqlalchemy\orm\base.py", line 423, in _inspect_mapped_class
    mapper._configure_all()
  File "E:\works\hyyb\.venv\Lib\site-packages\sqlalchemy\orm\mapper.py", line 1337, in _configure_all
    configure_mappers()
  File "E:\works\hyyb\.venv\Lib\site-packages\sqlalchemy\orm\mapper.py", line 3251, in configure_mappers
    raise e
sqlalchemy.exc.InvalidRequestError: One or more mappers failed to initialize - can't proceed with initialization of other mappers. Triggering mapper: 'mapped class Stuff->stuff'. Original exception was: Could not determine join condition between parent/child tables on relationship Stuff.attendances - there are no foreign keys linking these tables.  Ensure that referencing columns are associated with a ForeignKey or ForeignKeyConstraint, or specify a 'primaryjoin' expression.
2025-04-15 14:33:09,767 - hyyb - ERROR - Exception on /favicon.ico [GET]
Traceback (most recent call last):
  File "E:\works\hyyb\.venv\Lib\site-packages\flask\app.py", line 1950, in full_dispatch_request
    rv = self.dispatch_request()
         ^^^^^^^^^^^^^^^^^^^^^^^
  File "E:\works\hyyb\.venv\Lib\site-packages\flask\app.py", line 1926, in dispatch_request
    self.raise_routing_exception(req)
  File "E:\works\hyyb\.venv\Lib\site-packages\flask\app.py", line 1908, in raise_routing_exception
    raise request.routing_exception
  File "E:\works\hyyb\.venv\Lib\site-packages\flask\ctx.py", line 350, in match_request
    result = self.url_adapter.match(return_rule=True)
             ^^^^^^^^^^^^^^^^^^^^^^^^^^^^^^^^^^^^^^^^
  File "E:\works\hyyb\.venv\Lib\site-packages\werkzeug\routing.py", line 1945, in match
    raise NotFound()
werkzeug.exceptions.NotFound: 404 Not Found: The requested URL was not found on the server. If you entered the URL manually please check your spelling and try again.

During handling of the above exception, another exception occurred:

Traceback (most recent call last):
  File "E:\works\hyyb\.venv\Lib\site-packages\flask\app.py", line 2447, in wsgi_app
    response = self.full_dispatch_request()
               ^^^^^^^^^^^^^^^^^^^^^^^^^^^^
  File "E:\works\hyyb\.venv\Lib\site-packages\flask\app.py", line 1952, in full_dispatch_request
    rv = self.handle_user_exception(e)
         ^^^^^^^^^^^^^^^^^^^^^^^^^^^^^
  File "E:\works\hyyb\.venv\Lib\site-packages\flask\app.py", line 1816, in handle_user_exception
    return self.handle_http_exception(e)
           ^^^^^^^^^^^^^^^^^^^^^^^^^^^^^
  File "E:\works\hyyb\.venv\Lib\site-packages\flask\app.py", line 1744, in handle_http_exception
    return handler(e)
           ^^^^^^^^^^
  File "E:\works\hyyb\hyyb\__init__.py", line 144, in page_not_found
    return render_template('errors/404.html'), 404
           ^^^^^^^^^^^^^^^^^^^^^^^^^^^^^^^^^^
  File "E:\works\hyyb\.venv\Lib\site-packages\flask\templating.py", line 136, in render_template
    ctx.app.update_template_context(context)
  File "E:\works\hyyb\.venv\Lib\site-packages\flask\app.py", line 838, in update_template_context
    context.update(func())
                   ^^^^^^
  File "E:\works\hyyb\hyyb\__init__.py", line 111, in make_template_context
    admin = Admin.query.first()
            ^^^^^^^^^^^
  File "E:\works\hyyb\.venv\Lib\site-packages\flask_sqlalchemy\__init__.py", line 517, in __get__
    mapper = orm.class_mapper(type)
             ^^^^^^^^^^^^^^^^^^^^^^
  File "E:\works\hyyb\.venv\Lib\site-packages\sqlalchemy\orm\base.py", line 444, in class_mapper
    mapper = _inspect_mapped_class(class_, configure=configure)
             ^^^^^^^^^^^^^^^^^^^^^^^^^^^^^^^^^^^^^^^^^^^^^^^^^^
  File "E:\works\hyyb\.venv\Lib\site-packages\sqlalchemy\orm\base.py", line 423, in _inspect_mapped_class
    mapper._configure_all()
  File "E:\works\hyyb\.venv\Lib\site-packages\sqlalchemy\orm\mapper.py", line 1337, in _configure_all
    configure_mappers()
  File "E:\works\hyyb\.venv\Lib\site-packages\sqlalchemy\orm\mapper.py", line 3251, in configure_mappers
    raise e
sqlalchemy.exc.InvalidRequestError: One or more mappers failed to initialize - can't proceed with initialization of other mappers. Triggering mapper: 'mapped class Stuff->stuff'. Original exception was: Could not determine join condition between parent/child tables on relationship Stuff.attendances - there are no foreign keys linking these tables.  Ensure that referencing columns are associated with a ForeignKey or ForeignKeyConstraint, or specify a 'primaryjoin' expression.
2025-04-15 14:33:09,829 - hyyb - ERROR - Exception on /favicon.ico [GET]
Traceback (most recent call last):
  File "E:\works\hyyb\.venv\Lib\site-packages\flask\app.py", line 1950, in full_dispatch_request
    rv = self.dispatch_request()
         ^^^^^^^^^^^^^^^^^^^^^^^
  File "E:\works\hyyb\.venv\Lib\site-packages\flask\app.py", line 1926, in dispatch_request
    self.raise_routing_exception(req)
  File "E:\works\hyyb\.venv\Lib\site-packages\flask\app.py", line 1908, in raise_routing_exception
    raise request.routing_exception
  File "E:\works\hyyb\.venv\Lib\site-packages\flask\ctx.py", line 350, in match_request
    result = self.url_adapter.match(return_rule=True)
             ^^^^^^^^^^^^^^^^^^^^^^^^^^^^^^^^^^^^^^^^
  File "E:\works\hyyb\.venv\Lib\site-packages\werkzeug\routing.py", line 1945, in match
    raise NotFound()
werkzeug.exceptions.NotFound: 404 Not Found: The requested URL was not found on the server. If you entered the URL manually please check your spelling and try again.

During handling of the above exception, another exception occurred:

Traceback (most recent call last):
  File "E:\works\hyyb\.venv\Lib\site-packages\flask\app.py", line 2447, in wsgi_app
    response = self.full_dispatch_request()
               ^^^^^^^^^^^^^^^^^^^^^^^^^^^^
  File "E:\works\hyyb\.venv\Lib\site-packages\flask\app.py", line 1952, in full_dispatch_request
    rv = self.handle_user_exception(e)
         ^^^^^^^^^^^^^^^^^^^^^^^^^^^^^
  File "E:\works\hyyb\.venv\Lib\site-packages\flask\app.py", line 1816, in handle_user_exception
    return self.handle_http_exception(e)
           ^^^^^^^^^^^^^^^^^^^^^^^^^^^^^
  File "E:\works\hyyb\.venv\Lib\site-packages\flask\app.py", line 1744, in handle_http_exception
    return handler(e)
           ^^^^^^^^^^
  File "E:\works\hyyb\hyyb\__init__.py", line 144, in page_not_found
    return render_template('errors/404.html'), 404
           ^^^^^^^^^^^^^^^^^^^^^^^^^^^^^^^^^^
  File "E:\works\hyyb\.venv\Lib\site-packages\flask\templating.py", line 136, in render_template
    ctx.app.update_template_context(context)
  File "E:\works\hyyb\.venv\Lib\site-packages\flask\app.py", line 838, in update_template_context
    context.update(func())
                   ^^^^^^
  File "E:\works\hyyb\hyyb\__init__.py", line 111, in make_template_context
    admin = Admin.query.first()
            ^^^^^^^^^^^
  File "E:\works\hyyb\.venv\Lib\site-packages\flask_sqlalchemy\__init__.py", line 517, in __get__
    mapper = orm.class_mapper(type)
             ^^^^^^^^^^^^^^^^^^^^^^
  File "E:\works\hyyb\.venv\Lib\site-packages\sqlalchemy\orm\base.py", line 444, in class_mapper
    mapper = _inspect_mapped_class(class_, configure=configure)
             ^^^^^^^^^^^^^^^^^^^^^^^^^^^^^^^^^^^^^^^^^^^^^^^^^^
  File "E:\works\hyyb\.venv\Lib\site-packages\sqlalchemy\orm\base.py", line 423, in _inspect_mapped_class
    mapper._configure_all()
  File "E:\works\hyyb\.venv\Lib\site-packages\sqlalchemy\orm\mapper.py", line 1337, in _configure_all
    configure_mappers()
  File "E:\works\hyyb\.venv\Lib\site-packages\sqlalchemy\orm\mapper.py", line 3251, in configure_mappers
    raise e
sqlalchemy.exc.InvalidRequestError: One or more mappers failed to initialize - can't proceed with initialization of other mappers. Triggering mapper: 'mapped class Stuff->stuff'. Original exception was: Could not determine join condition between parent/child tables on relationship Stuff.attendances - there are no foreign keys linking these tables.  Ensure that referencing columns are associated with a ForeignKey or ForeignKeyConstraint, or specify a 'primaryjoin' expression.
2025-04-15 14:58:35,230 - hyyb - ERROR - Exception on /auth/login [GET]
Traceback (most recent call last):
  File "E:\works\hyyb\.venv\Lib\site-packages\sqlalchemy\orm\mapper.py", line 2046, in get_property
    return self._props[key]
           ~~~~~~~~~~~^^^^^
KeyError: 'dpartmentp'

The above exception was the direct cause of the following exception:

Traceback (most recent call last):
  File "E:\works\hyyb\.venv\Lib\site-packages\flask\app.py", line 2447, in wsgi_app
    response = self.full_dispatch_request()
               ^^^^^^^^^^^^^^^^^^^^^^^^^^^^
  File "E:\works\hyyb\.venv\Lib\site-packages\flask\app.py", line 1952, in full_dispatch_request
    rv = self.handle_user_exception(e)
         ^^^^^^^^^^^^^^^^^^^^^^^^^^^^^
  File "E:\works\hyyb\.venv\Lib\site-packages\flask\app.py", line 1821, in handle_user_exception
    reraise(exc_type, exc_value, tb)
  File "E:\works\hyyb\.venv\Lib\site-packages\flask\_compat.py", line 39, in reraise
    raise value
  File "E:\works\hyyb\.venv\Lib\site-packages\flask\app.py", line 1950, in full_dispatch_request
    rv = self.dispatch_request()
         ^^^^^^^^^^^^^^^^^^^^^^^
  File "E:\works\hyyb\.venv\Lib\site-packages\flask\app.py", line 1936, in dispatch_request
    return self.view_functions[rule.endpoint](**req.view_args)
           ^^^^^^^^^^^^^^^^^^^^^^^^^^^^^^^^^^^^^^^^^^^^^^^^^^^
  File "E:\works\hyyb\hyyb\blueprints\auth.py", line 35, in login
    return render_template('auth/login.html', form=form) #
           ^^^^^^^^^^^^^^^^^^^^^^^^^^^^^^^^^^^^^^^^^^^^^
  File "E:\works\hyyb\.venv\Lib\site-packages\flask\templating.py", line 136, in render_template
    ctx.app.update_template_context(context)
  File "E:\works\hyyb\.venv\Lib\site-packages\flask\app.py", line 838, in update_template_context
    context.update(func())
                   ^^^^^^
  File "E:\works\hyyb\hyyb\__init__.py", line 111, in make_template_context
    admin = Admin.query.first()
            ^^^^^^^^^^^
  File "E:\works\hyyb\.venv\Lib\site-packages\flask_sqlalchemy\__init__.py", line 517, in __get__
    mapper = orm.class_mapper(type)
             ^^^^^^^^^^^^^^^^^^^^^^
  File "E:\works\hyyb\.venv\Lib\site-packages\sqlalchemy\orm\base.py", line 444, in class_mapper
    mapper = _inspect_mapped_class(class_, configure=configure)
             ^^^^^^^^^^^^^^^^^^^^^^^^^^^^^^^^^^^^^^^^^^^^^^^^^^
  File "E:\works\hyyb\.venv\Lib\site-packages\sqlalchemy\orm\base.py", line 423, in _inspect_mapped_class
    mapper._configure_all()
  File "E:\works\hyyb\.venv\Lib\site-packages\sqlalchemy\orm\mapper.py", line 1337, in _configure_all
    configure_mappers()
  File "E:\works\hyyb\.venv\Lib\site-packages\sqlalchemy\orm\mapper.py", line 3255, in configure_mappers
    mapper._post_configure_properties()
  File "E:\works\hyyb\.venv\Lib\site-packages\sqlalchemy\orm\mapper.py", line 1950, in _post_configure_properties
    prop.init()
  File "E:\works\hyyb\.venv\Lib\site-packages\sqlalchemy\orm\interfaces.py", line 196, in init
    self.do_init()
  File "E:\works\hyyb\.venv\Lib\site-packages\sqlalchemy\orm\relationships.py", line 1939, in do_init
    self._generate_backref()
  File "E:\works\hyyb\.venv\Lib\site-packages\sqlalchemy\orm\relationships.py", line 2224, in _generate_backref
    self._add_reverse_property(self.back_populates)
  File "E:\works\hyyb\.venv\Lib\site-packages\sqlalchemy\orm\relationships.py", line 1862, in _add_reverse_property
    other = self.mapper.get_property(key, _configure_mappers=False)
            ^^^^^^^^^^^^^^^^^^^^^^^^^^^^^^^^^^^^^^^^^^^^^^^^^^^^^^^
  File "E:\works\hyyb\.venv\Lib\site-packages\sqlalchemy\orm\mapper.py", line 2048, in get_property
    util.raise_(
  File "E:\works\hyyb\.venv\Lib\site-packages\sqlalchemy\util\compat.py", line 178, in raise_
    raise exception
sqlalchemy.exc.InvalidRequestError: Mapper 'mapped class Spare->spare' has no property 'dpartmentp'
2025-04-15 14:58:35,670 - hyyb - ERROR - Exception on /favicon.ico [GET]
Traceback (most recent call last):
  File "E:\works\hyyb\.venv\Lib\site-packages\flask\app.py", line 1950, in full_dispatch_request
    rv = self.dispatch_request()
         ^^^^^^^^^^^^^^^^^^^^^^^
  File "E:\works\hyyb\.venv\Lib\site-packages\flask\app.py", line 1926, in dispatch_request
    self.raise_routing_exception(req)
  File "E:\works\hyyb\.venv\Lib\site-packages\flask\app.py", line 1908, in raise_routing_exception
    raise request.routing_exception
  File "E:\works\hyyb\.venv\Lib\site-packages\flask\ctx.py", line 350, in match_request
    result = self.url_adapter.match(return_rule=True)
             ^^^^^^^^^^^^^^^^^^^^^^^^^^^^^^^^^^^^^^^^
  File "E:\works\hyyb\.venv\Lib\site-packages\werkzeug\routing.py", line 1945, in match
    raise NotFound()
werkzeug.exceptions.NotFound: 404 Not Found: The requested URL was not found on the server. If you entered the URL manually please check your spelling and try again.

During handling of the above exception, another exception occurred:

Traceback (most recent call last):
  File "E:\works\hyyb\.venv\Lib\site-packages\flask\app.py", line 2447, in wsgi_app
    response = self.full_dispatch_request()
               ^^^^^^^^^^^^^^^^^^^^^^^^^^^^
  File "E:\works\hyyb\.venv\Lib\site-packages\flask\app.py", line 1952, in full_dispatch_request
    rv = self.handle_user_exception(e)
         ^^^^^^^^^^^^^^^^^^^^^^^^^^^^^
  File "E:\works\hyyb\.venv\Lib\site-packages\flask\app.py", line 1816, in handle_user_exception
    return self.handle_http_exception(e)
           ^^^^^^^^^^^^^^^^^^^^^^^^^^^^^
  File "E:\works\hyyb\.venv\Lib\site-packages\flask\app.py", line 1744, in handle_http_exception
    return handler(e)
           ^^^^^^^^^^
  File "E:\works\hyyb\hyyb\__init__.py", line 144, in page_not_found
    return render_template('errors/404.html'), 404
           ^^^^^^^^^^^^^^^^^^^^^^^^^^^^^^^^^^
  File "E:\works\hyyb\.venv\Lib\site-packages\flask\templating.py", line 136, in render_template
    ctx.app.update_template_context(context)
  File "E:\works\hyyb\.venv\Lib\site-packages\flask\app.py", line 838, in update_template_context
    context.update(func())
                   ^^^^^^
  File "E:\works\hyyb\hyyb\__init__.py", line 111, in make_template_context
    admin = Admin.query.first()
            ^^^^^^^^^^^
  File "E:\works\hyyb\.venv\Lib\site-packages\flask_sqlalchemy\__init__.py", line 517, in __get__
    mapper = orm.class_mapper(type)
             ^^^^^^^^^^^^^^^^^^^^^^
  File "E:\works\hyyb\.venv\Lib\site-packages\sqlalchemy\orm\base.py", line 444, in class_mapper
    mapper = _inspect_mapped_class(class_, configure=configure)
             ^^^^^^^^^^^^^^^^^^^^^^^^^^^^^^^^^^^^^^^^^^^^^^^^^^
  File "E:\works\hyyb\.venv\Lib\site-packages\sqlalchemy\orm\base.py", line 423, in _inspect_mapped_class
    mapper._configure_all()
  File "E:\works\hyyb\.venv\Lib\site-packages\sqlalchemy\orm\mapper.py", line 1337, in _configure_all
    configure_mappers()
  File "E:\works\hyyb\.venv\Lib\site-packages\sqlalchemy\orm\mapper.py", line 3251, in configure_mappers
    raise e
sqlalchemy.exc.InvalidRequestError: One or more mappers failed to initialize - can't proceed with initialization of other mappers. Triggering mapper: 'mapped class Departmentp->departmentp'. Original exception was: Mapper 'mapped class Spare->spare' has no property 'dpartmentp'
2025-04-15 15:00:12,165 - hyyb - ERROR - Exception on /auth/login [GET]
Traceback (most recent call last):
  File "E:\works\hyyb\.venv\Lib\site-packages\sqlalchemy\orm\mapper.py", line 2046, in get_property
    return self._props[key]
           ~~~~~~~~~~~^^^^^
KeyError: 'dpartmentp'

The above exception was the direct cause of the following exception:

Traceback (most recent call last):
  File "E:\works\hyyb\.venv\Lib\site-packages\flask\app.py", line 2447, in wsgi_app
    response = self.full_dispatch_request()
               ^^^^^^^^^^^^^^^^^^^^^^^^^^^^
  File "E:\works\hyyb\.venv\Lib\site-packages\flask\app.py", line 1952, in full_dispatch_request
    rv = self.handle_user_exception(e)
         ^^^^^^^^^^^^^^^^^^^^^^^^^^^^^
  File "E:\works\hyyb\.venv\Lib\site-packages\flask\app.py", line 1821, in handle_user_exception
    reraise(exc_type, exc_value, tb)
  File "E:\works\hyyb\.venv\Lib\site-packages\flask\_compat.py", line 39, in reraise
    raise value
  File "E:\works\hyyb\.venv\Lib\site-packages\flask\app.py", line 1950, in full_dispatch_request
    rv = self.dispatch_request()
         ^^^^^^^^^^^^^^^^^^^^^^^
  File "E:\works\hyyb\.venv\Lib\site-packages\flask\app.py", line 1936, in dispatch_request
    return self.view_functions[rule.endpoint](**req.view_args)
           ^^^^^^^^^^^^^^^^^^^^^^^^^^^^^^^^^^^^^^^^^^^^^^^^^^^
  File "E:\works\hyyb\hyyb\blueprints\auth.py", line 35, in login
    return render_template('auth/login.html', form=form) #
           ^^^^^^^^^^^^^^^^^^^^^^^^^^^^^^^^^^^^^^^^^^^^^
  File "E:\works\hyyb\.venv\Lib\site-packages\flask\templating.py", line 136, in render_template
    ctx.app.update_template_context(context)
  File "E:\works\hyyb\.venv\Lib\site-packages\flask\app.py", line 838, in update_template_context
    context.update(func())
                   ^^^^^^
  File "E:\works\hyyb\hyyb\__init__.py", line 111, in make_template_context
    admin = Admin.query.first()
            ^^^^^^^^^^^
  File "E:\works\hyyb\.venv\Lib\site-packages\flask_sqlalchemy\__init__.py", line 517, in __get__
    mapper = orm.class_mapper(type)
             ^^^^^^^^^^^^^^^^^^^^^^
  File "E:\works\hyyb\.venv\Lib\site-packages\sqlalchemy\orm\base.py", line 444, in class_mapper
    mapper = _inspect_mapped_class(class_, configure=configure)
             ^^^^^^^^^^^^^^^^^^^^^^^^^^^^^^^^^^^^^^^^^^^^^^^^^^
  File "E:\works\hyyb\.venv\Lib\site-packages\sqlalchemy\orm\base.py", line 423, in _inspect_mapped_class
    mapper._configure_all()
  File "E:\works\hyyb\.venv\Lib\site-packages\sqlalchemy\orm\mapper.py", line 1337, in _configure_all
    configure_mappers()
  File "E:\works\hyyb\.venv\Lib\site-packages\sqlalchemy\orm\mapper.py", line 3255, in configure_mappers
    mapper._post_configure_properties()
  File "E:\works\hyyb\.venv\Lib\site-packages\sqlalchemy\orm\mapper.py", line 1950, in _post_configure_properties
    prop.init()
  File "E:\works\hyyb\.venv\Lib\site-packages\sqlalchemy\orm\interfaces.py", line 196, in init
    self.do_init()
  File "E:\works\hyyb\.venv\Lib\site-packages\sqlalchemy\orm\relationships.py", line 1939, in do_init
    self._generate_backref()
  File "E:\works\hyyb\.venv\Lib\site-packages\sqlalchemy\orm\relationships.py", line 2224, in _generate_backref
    self._add_reverse_property(self.back_populates)
  File "E:\works\hyyb\.venv\Lib\site-packages\sqlalchemy\orm\relationships.py", line 1862, in _add_reverse_property
    other = self.mapper.get_property(key, _configure_mappers=False)
            ^^^^^^^^^^^^^^^^^^^^^^^^^^^^^^^^^^^^^^^^^^^^^^^^^^^^^^^
  File "E:\works\hyyb\.venv\Lib\site-packages\sqlalchemy\orm\mapper.py", line 2048, in get_property
    util.raise_(
  File "E:\works\hyyb\.venv\Lib\site-packages\sqlalchemy\util\compat.py", line 178, in raise_
    raise exception
sqlalchemy.exc.InvalidRequestError: Mapper 'mapped class Spare->spare' has no property 'dpartmentp'
2025-04-15 15:00:12,277 - hyyb - ERROR - Exception on /favicon.ico [GET]
Traceback (most recent call last):
  File "E:\works\hyyb\.venv\Lib\site-packages\flask\app.py", line 1950, in full_dispatch_request
    rv = self.dispatch_request()
         ^^^^^^^^^^^^^^^^^^^^^^^
  File "E:\works\hyyb\.venv\Lib\site-packages\flask\app.py", line 1926, in dispatch_request
    self.raise_routing_exception(req)
  File "E:\works\hyyb\.venv\Lib\site-packages\flask\app.py", line 1908, in raise_routing_exception
    raise request.routing_exception
  File "E:\works\hyyb\.venv\Lib\site-packages\flask\ctx.py", line 350, in match_request
    result = self.url_adapter.match(return_rule=True)
             ^^^^^^^^^^^^^^^^^^^^^^^^^^^^^^^^^^^^^^^^
  File "E:\works\hyyb\.venv\Lib\site-packages\werkzeug\routing.py", line 1945, in match
    raise NotFound()
werkzeug.exceptions.NotFound: 404 Not Found: The requested URL was not found on the server. If you entered the URL manually please check your spelling and try again.

During handling of the above exception, another exception occurred:

Traceback (most recent call last):
  File "E:\works\hyyb\.venv\Lib\site-packages\flask\app.py", line 2447, in wsgi_app
    response = self.full_dispatch_request()
               ^^^^^^^^^^^^^^^^^^^^^^^^^^^^
  File "E:\works\hyyb\.venv\Lib\site-packages\flask\app.py", line 1952, in full_dispatch_request
    rv = self.handle_user_exception(e)
         ^^^^^^^^^^^^^^^^^^^^^^^^^^^^^
  File "E:\works\hyyb\.venv\Lib\site-packages\flask\app.py", line 1816, in handle_user_exception
    return self.handle_http_exception(e)
           ^^^^^^^^^^^^^^^^^^^^^^^^^^^^^
  File "E:\works\hyyb\.venv\Lib\site-packages\flask\app.py", line 1744, in handle_http_exception
    return handler(e)
           ^^^^^^^^^^
  File "E:\works\hyyb\hyyb\__init__.py", line 144, in page_not_found
    return render_template('errors/404.html'), 404
           ^^^^^^^^^^^^^^^^^^^^^^^^^^^^^^^^^^
  File "E:\works\hyyb\.venv\Lib\site-packages\flask\templating.py", line 136, in render_template
    ctx.app.update_template_context(context)
  File "E:\works\hyyb\.venv\Lib\site-packages\flask\app.py", line 838, in update_template_context
    context.update(func())
                   ^^^^^^
  File "E:\works\hyyb\hyyb\__init__.py", line 111, in make_template_context
    admin = Admin.query.first()
            ^^^^^^^^^^^
  File "E:\works\hyyb\.venv\Lib\site-packages\flask_sqlalchemy\__init__.py", line 517, in __get__
    mapper = orm.class_mapper(type)
             ^^^^^^^^^^^^^^^^^^^^^^
  File "E:\works\hyyb\.venv\Lib\site-packages\sqlalchemy\orm\base.py", line 444, in class_mapper
    mapper = _inspect_mapped_class(class_, configure=configure)
             ^^^^^^^^^^^^^^^^^^^^^^^^^^^^^^^^^^^^^^^^^^^^^^^^^^
  File "E:\works\hyyb\.venv\Lib\site-packages\sqlalchemy\orm\base.py", line 423, in _inspect_mapped_class
    mapper._configure_all()
  File "E:\works\hyyb\.venv\Lib\site-packages\sqlalchemy\orm\mapper.py", line 1337, in _configure_all
    configure_mappers()
  File "E:\works\hyyb\.venv\Lib\site-packages\sqlalchemy\orm\mapper.py", line 3251, in configure_mappers
    raise e
sqlalchemy.exc.InvalidRequestError: One or more mappers failed to initialize - can't proceed with initialization of other mappers. Triggering mapper: 'mapped class Departmentp->departmentp'. Original exception was: Mapper 'mapped class Spare->spare' has no property 'dpartmentp'
2025-04-15 16:30:35,401 - hyyb - ERROR - Exception on /auth/login [GET]
Traceback (most recent call last):
  File "E:\works\hyyb\.venv\Lib\site-packages\sqlalchemy\orm\mapper.py", line 2046, in get_property
    return self._props[key]
           ~~~~~~~~~~~^^^^^
KeyError: 'dpartmentp'

The above exception was the direct cause of the following exception:

Traceback (most recent call last):
  File "E:\works\hyyb\.venv\Lib\site-packages\flask\app.py", line 2447, in wsgi_app
    response = self.full_dispatch_request()
               ^^^^^^^^^^^^^^^^^^^^^^^^^^^^
  File "E:\works\hyyb\.venv\Lib\site-packages\flask\app.py", line 1952, in full_dispatch_request
    rv = self.handle_user_exception(e)
         ^^^^^^^^^^^^^^^^^^^^^^^^^^^^^
  File "E:\works\hyyb\.venv\Lib\site-packages\flask\app.py", line 1821, in handle_user_exception
    reraise(exc_type, exc_value, tb)
  File "E:\works\hyyb\.venv\Lib\site-packages\flask\_compat.py", line 39, in reraise
    raise value
  File "E:\works\hyyb\.venv\Lib\site-packages\flask\app.py", line 1950, in full_dispatch_request
    rv = self.dispatch_request()
         ^^^^^^^^^^^^^^^^^^^^^^^
  File "E:\works\hyyb\.venv\Lib\site-packages\flask\app.py", line 1936, in dispatch_request
    return self.view_functions[rule.endpoint](**req.view_args)
           ^^^^^^^^^^^^^^^^^^^^^^^^^^^^^^^^^^^^^^^^^^^^^^^^^^^
  File "E:\works\hyyb\hyyb\blueprints\auth.py", line 35, in login
    return render_template('auth/login.html', form=form) #
           ^^^^^^^^^^^^^^^^^^^^^^^^^^^^^^^^^^^^^^^^^^^^^
  File "E:\works\hyyb\.venv\Lib\site-packages\flask\templating.py", line 136, in render_template
    ctx.app.update_template_context(context)
  File "E:\works\hyyb\.venv\Lib\site-packages\flask\app.py", line 838, in update_template_context
    context.update(func())
                   ^^^^^^
  File "E:\works\hyyb\hyyb\__init__.py", line 111, in make_template_context
    admin = Admin.query.first()
            ^^^^^^^^^^^
  File "E:\works\hyyb\.venv\Lib\site-packages\flask_sqlalchemy\__init__.py", line 517, in __get__
    mapper = orm.class_mapper(type)
             ^^^^^^^^^^^^^^^^^^^^^^
  File "E:\works\hyyb\.venv\Lib\site-packages\sqlalchemy\orm\base.py", line 444, in class_mapper
    mapper = _inspect_mapped_class(class_, configure=configure)
             ^^^^^^^^^^^^^^^^^^^^^^^^^^^^^^^^^^^^^^^^^^^^^^^^^^
  File "E:\works\hyyb\.venv\Lib\site-packages\sqlalchemy\orm\base.py", line 423, in _inspect_mapped_class
    mapper._configure_all()
  File "E:\works\hyyb\.venv\Lib\site-packages\sqlalchemy\orm\mapper.py", line 1337, in _configure_all
    configure_mappers()
  File "E:\works\hyyb\.venv\Lib\site-packages\sqlalchemy\orm\mapper.py", line 3255, in configure_mappers
    mapper._post_configure_properties()
  File "E:\works\hyyb\.venv\Lib\site-packages\sqlalchemy\orm\mapper.py", line 1950, in _post_configure_properties
    prop.init()
  File "E:\works\hyyb\.venv\Lib\site-packages\sqlalchemy\orm\interfaces.py", line 196, in init
    self.do_init()
  File "E:\works\hyyb\.venv\Lib\site-packages\sqlalchemy\orm\relationships.py", line 1939, in do_init
    self._generate_backref()
  File "E:\works\hyyb\.venv\Lib\site-packages\sqlalchemy\orm\relationships.py", line 2224, in _generate_backref
    self._add_reverse_property(self.back_populates)
  File "E:\works\hyyb\.venv\Lib\site-packages\sqlalchemy\orm\relationships.py", line 1862, in _add_reverse_property
    other = self.mapper.get_property(key, _configure_mappers=False)
            ^^^^^^^^^^^^^^^^^^^^^^^^^^^^^^^^^^^^^^^^^^^^^^^^^^^^^^^
  File "E:\works\hyyb\.venv\Lib\site-packages\sqlalchemy\orm\mapper.py", line 2048, in get_property
    util.raise_(
  File "E:\works\hyyb\.venv\Lib\site-packages\sqlalchemy\util\compat.py", line 178, in raise_
    raise exception
sqlalchemy.exc.InvalidRequestError: Mapper 'mapped class Spare->spare' has no property 'dpartmentp'
2025-04-15 16:30:35,603 - hyyb - ERROR - Exception on /favicon.ico [GET]
Traceback (most recent call last):
  File "E:\works\hyyb\.venv\Lib\site-packages\flask\app.py", line 1950, in full_dispatch_request
    rv = self.dispatch_request()
         ^^^^^^^^^^^^^^^^^^^^^^^
  File "E:\works\hyyb\.venv\Lib\site-packages\flask\app.py", line 1926, in dispatch_request
    self.raise_routing_exception(req)
  File "E:\works\hyyb\.venv\Lib\site-packages\flask\app.py", line 1908, in raise_routing_exception
    raise request.routing_exception
  File "E:\works\hyyb\.venv\Lib\site-packages\flask\ctx.py", line 350, in match_request
    result = self.url_adapter.match(return_rule=True)
             ^^^^^^^^^^^^^^^^^^^^^^^^^^^^^^^^^^^^^^^^
  File "E:\works\hyyb\.venv\Lib\site-packages\werkzeug\routing.py", line 1945, in match
    raise NotFound()
werkzeug.exceptions.NotFound: 404 Not Found: The requested URL was not found on the server. If you entered the URL manually please check your spelling and try again.

During handling of the above exception, another exception occurred:

Traceback (most recent call last):
  File "E:\works\hyyb\.venv\Lib\site-packages\flask\app.py", line 2447, in wsgi_app
    response = self.full_dispatch_request()
               ^^^^^^^^^^^^^^^^^^^^^^^^^^^^
  File "E:\works\hyyb\.venv\Lib\site-packages\flask\app.py", line 1952, in full_dispatch_request
    rv = self.handle_user_exception(e)
         ^^^^^^^^^^^^^^^^^^^^^^^^^^^^^
  File "E:\works\hyyb\.venv\Lib\site-packages\flask\app.py", line 1816, in handle_user_exception
    return self.handle_http_exception(e)
           ^^^^^^^^^^^^^^^^^^^^^^^^^^^^^
  File "E:\works\hyyb\.venv\Lib\site-packages\flask\app.py", line 1744, in handle_http_exception
    return handler(e)
           ^^^^^^^^^^
  File "E:\works\hyyb\hyyb\__init__.py", line 144, in page_not_found
    return render_template('errors/404.html'), 404
           ^^^^^^^^^^^^^^^^^^^^^^^^^^^^^^^^^^
  File "E:\works\hyyb\.venv\Lib\site-packages\flask\templating.py", line 136, in render_template
    ctx.app.update_template_context(context)
  File "E:\works\hyyb\.venv\Lib\site-packages\flask\app.py", line 838, in update_template_context
    context.update(func())
                   ^^^^^^
  File "E:\works\hyyb\hyyb\__init__.py", line 111, in make_template_context
    admin = Admin.query.first()
            ^^^^^^^^^^^
  File "E:\works\hyyb\.venv\Lib\site-packages\flask_sqlalchemy\__init__.py", line 517, in __get__
    mapper = orm.class_mapper(type)
             ^^^^^^^^^^^^^^^^^^^^^^
  File "E:\works\hyyb\.venv\Lib\site-packages\sqlalchemy\orm\base.py", line 444, in class_mapper
    mapper = _inspect_mapped_class(class_, configure=configure)
             ^^^^^^^^^^^^^^^^^^^^^^^^^^^^^^^^^^^^^^^^^^^^^^^^^^
  File "E:\works\hyyb\.venv\Lib\site-packages\sqlalchemy\orm\base.py", line 423, in _inspect_mapped_class
    mapper._configure_all()
  File "E:\works\hyyb\.venv\Lib\site-packages\sqlalchemy\orm\mapper.py", line 1337, in _configure_all
    configure_mappers()
  File "E:\works\hyyb\.venv\Lib\site-packages\sqlalchemy\orm\mapper.py", line 3251, in configure_mappers
    raise e
sqlalchemy.exc.InvalidRequestError: One or more mappers failed to initialize - can't proceed with initialization of other mappers. Triggering mapper: 'mapped class Departmentp->departmentp'. Original exception was: Mapper 'mapped class Spare->spare' has no property 'dpartmentp'
2025-04-15 16:58:07,560 - hyyb - ERROR - Exception on /auth/login [GET]
Traceback (most recent call last):
  File "E:\works\hyyb\.venv\Lib\site-packages\sqlalchemy\engine\base.py", line 1247, in _execute_context
    self.dialect.do_execute(
  File "E:\works\hyyb\.venv\Lib\site-packages\sqlalchemy\engine\default.py", line 588, in do_execute
    cursor.execute(statement, parameters)
sqlite3.OperationalError: no such table: admin

The above exception was the direct cause of the following exception:

Traceback (most recent call last):
  File "E:\works\hyyb\.venv\Lib\site-packages\flask\app.py", line 2447, in wsgi_app
    response = self.full_dispatch_request()
               ^^^^^^^^^^^^^^^^^^^^^^^^^^^^
  File "E:\works\hyyb\.venv\Lib\site-packages\flask\app.py", line 1952, in full_dispatch_request
    rv = self.handle_user_exception(e)
         ^^^^^^^^^^^^^^^^^^^^^^^^^^^^^
  File "E:\works\hyyb\.venv\Lib\site-packages\flask\app.py", line 1821, in handle_user_exception
    reraise(exc_type, exc_value, tb)
  File "E:\works\hyyb\.venv\Lib\site-packages\flask\_compat.py", line 39, in reraise
    raise value
  File "E:\works\hyyb\.venv\Lib\site-packages\flask\app.py", line 1950, in full_dispatch_request
    rv = self.dispatch_request()
         ^^^^^^^^^^^^^^^^^^^^^^^
  File "E:\works\hyyb\.venv\Lib\site-packages\flask\app.py", line 1936, in dispatch_request
    return self.view_functions[rule.endpoint](**req.view_args)
           ^^^^^^^^^^^^^^^^^^^^^^^^^^^^^^^^^^^^^^^^^^^^^^^^^^^
  File "E:\works\hyyb\hyyb\blueprints\auth.py", line 35, in login
    return render_template('auth/login.html', form=form) #
           ^^^^^^^^^^^^^^^^^^^^^^^^^^^^^^^^^^^^^^^^^^^^^
  File "E:\works\hyyb\.venv\Lib\site-packages\flask\templating.py", line 136, in render_template
    ctx.app.update_template_context(context)
  File "E:\works\hyyb\.venv\Lib\site-packages\flask\app.py", line 838, in update_template_context
    context.update(func())
                   ^^^^^^
  File "E:\works\hyyb\hyyb\__init__.py", line 166, in make_template_context
    admin = Admin.query.first()
            ^^^^^^^^^^^^^^^^^^^
  File "E:\works\hyyb\.venv\Lib\site-packages\sqlalchemy\orm\query.py", line 3298, in first
    ret = list(self[0:1])
               ~~~~^^^^^
  File "E:\works\hyyb\.venv\Lib\site-packages\sqlalchemy\orm\query.py", line 3076, in __getitem__
    return list(res)
           ^^^^^^^^^
  File "E:\works\hyyb\.venv\Lib\site-packages\sqlalchemy\orm\query.py", line 3403, in __iter__
    return self._execute_and_instances(context)
           ^^^^^^^^^^^^^^^^^^^^^^^^^^^^^^^^^^^^
  File "E:\works\hyyb\.venv\Lib\site-packages\sqlalchemy\orm\query.py", line 3428, in _execute_and_instances
    result = conn.execute(querycontext.statement, self._params)
             ^^^^^^^^^^^^^^^^^^^^^^^^^^^^^^^^^^^^^^^^^^^^^^^^^^
  File "E:\works\hyyb\.venv\Lib\site-packages\sqlalchemy\engine\base.py", line 984, in execute
    return meth(self, multiparams, params)
           ^^^^^^^^^^^^^^^^^^^^^^^^^^^^^^^
  File "E:\works\hyyb\.venv\Lib\site-packages\sqlalchemy\sql\elements.py", line 293, in _execute_on_connection
    return connection._execute_clauseelement(self, multiparams, params)
           ^^^^^^^^^^^^^^^^^^^^^^^^^^^^^^^^^^^^^^^^^^^^^^^^^^^^^^^^^^^^
  File "E:\works\hyyb\.venv\Lib\site-packages\sqlalchemy\engine\base.py", line 1097, in _execute_clauseelement
    ret = self._execute_context(
          ^^^^^^^^^^^^^^^^^^^^^^
  File "E:\works\hyyb\.venv\Lib\site-packages\sqlalchemy\engine\base.py", line 1287, in _execute_context
    self._handle_dbapi_exception(
  File "E:\works\hyyb\.venv\Lib\site-packages\sqlalchemy\engine\base.py", line 1481, in _handle_dbapi_exception
    util.raise_(
  File "E:\works\hyyb\.venv\Lib\site-packages\sqlalchemy\util\compat.py", line 178, in raise_
    raise exception
  File "E:\works\hyyb\.venv\Lib\site-packages\sqlalchemy\engine\base.py", line 1247, in _execute_context
    self.dialect.do_execute(
  File "E:\works\hyyb\.venv\Lib\site-packages\sqlalchemy\engine\default.py", line 588, in do_execute
    cursor.execute(statement, parameters)
sqlalchemy.exc.OperationalError: (sqlite3.OperationalError) no such table: admin
[SQL: SELECT admin.id AS admin_id, admin.username AS admin_username, admin.password_hash AS admin_password_hash, admin.privilege AS admin_privilege, admin.title AS admin_title, admin.others AS admin_others 
FROM admin
 LIMIT ? OFFSET ?]
[parameters: (1, 0)]
(Background on this error at: http://sqlalche.me/e/e3q8)
2025-04-15 16:58:07,693 - hyyb - ERROR - Exception on /favicon.ico [GET]
Traceback (most recent call last):
  File "E:\works\hyyb\.venv\Lib\site-packages\flask\app.py", line 1950, in full_dispatch_request
    rv = self.dispatch_request()
         ^^^^^^^^^^^^^^^^^^^^^^^
  File "E:\works\hyyb\.venv\Lib\site-packages\flask\app.py", line 1926, in dispatch_request
    self.raise_routing_exception(req)
  File "E:\works\hyyb\.venv\Lib\site-packages\flask\app.py", line 1908, in raise_routing_exception
    raise request.routing_exception
  File "E:\works\hyyb\.venv\Lib\site-packages\flask\ctx.py", line 350, in match_request
    result = self.url_adapter.match(return_rule=True)
             ^^^^^^^^^^^^^^^^^^^^^^^^^^^^^^^^^^^^^^^^
  File "E:\works\hyyb\.venv\Lib\site-packages\werkzeug\routing.py", line 1945, in match
    raise NotFound()
werkzeug.exceptions.NotFound: 404 Not Found: The requested URL was not found on the server. If you entered the URL manually please check your spelling and try again.

During handling of the above exception, another exception occurred:

Traceback (most recent call last):
  File "E:\works\hyyb\.venv\Lib\site-packages\sqlalchemy\engine\base.py", line 1247, in _execute_context
    self.dialect.do_execute(
  File "E:\works\hyyb\.venv\Lib\site-packages\sqlalchemy\engine\default.py", line 588, in do_execute
    cursor.execute(statement, parameters)
sqlite3.OperationalError: no such table: admin

The above exception was the direct cause of the following exception:

Traceback (most recent call last):
  File "E:\works\hyyb\.venv\Lib\site-packages\flask\app.py", line 2447, in wsgi_app
    response = self.full_dispatch_request()
               ^^^^^^^^^^^^^^^^^^^^^^^^^^^^
  File "E:\works\hyyb\.venv\Lib\site-packages\flask\app.py", line 1952, in full_dispatch_request
    rv = self.handle_user_exception(e)
         ^^^^^^^^^^^^^^^^^^^^^^^^^^^^^
  File "E:\works\hyyb\.venv\Lib\site-packages\flask\app.py", line 1816, in handle_user_exception
    return self.handle_http_exception(e)
           ^^^^^^^^^^^^^^^^^^^^^^^^^^^^^
  File "E:\works\hyyb\.venv\Lib\site-packages\flask\app.py", line 1744, in handle_http_exception
    return handler(e)
           ^^^^^^^^^^
  File "E:\works\hyyb\hyyb\__init__.py", line 199, in page_not_found
    return render_template('errors/404.html'), 404
           ^^^^^^^^^^^^^^^^^^^^^^^^^^^^^^^^^^
  File "E:\works\hyyb\.venv\Lib\site-packages\flask\templating.py", line 136, in render_template
    ctx.app.update_template_context(context)
  File "E:\works\hyyb\.venv\Lib\site-packages\flask\app.py", line 838, in update_template_context
    context.update(func())
                   ^^^^^^
  File "E:\works\hyyb\hyyb\__init__.py", line 166, in make_template_context
    admin = Admin.query.first()
            ^^^^^^^^^^^^^^^^^^^
  File "E:\works\hyyb\.venv\Lib\site-packages\sqlalchemy\orm\query.py", line 3298, in first
    ret = list(self[0:1])
               ~~~~^^^^^
  File "E:\works\hyyb\.venv\Lib\site-packages\sqlalchemy\orm\query.py", line 3076, in __getitem__
    return list(res)
           ^^^^^^^^^
  File "E:\works\hyyb\.venv\Lib\site-packages\sqlalchemy\orm\query.py", line 3403, in __iter__
    return self._execute_and_instances(context)
           ^^^^^^^^^^^^^^^^^^^^^^^^^^^^^^^^^^^^
  File "E:\works\hyyb\.venv\Lib\site-packages\sqlalchemy\orm\query.py", line 3428, in _execute_and_instances
    result = conn.execute(querycontext.statement, self._params)
             ^^^^^^^^^^^^^^^^^^^^^^^^^^^^^^^^^^^^^^^^^^^^^^^^^^
  File "E:\works\hyyb\.venv\Lib\site-packages\sqlalchemy\engine\base.py", line 984, in execute
    return meth(self, multiparams, params)
           ^^^^^^^^^^^^^^^^^^^^^^^^^^^^^^^
  File "E:\works\hyyb\.venv\Lib\site-packages\sqlalchemy\sql\elements.py", line 293, in _execute_on_connection
    return connection._execute_clauseelement(self, multiparams, params)
           ^^^^^^^^^^^^^^^^^^^^^^^^^^^^^^^^^^^^^^^^^^^^^^^^^^^^^^^^^^^^
  File "E:\works\hyyb\.venv\Lib\site-packages\sqlalchemy\engine\base.py", line 1097, in _execute_clauseelement
    ret = self._execute_context(
          ^^^^^^^^^^^^^^^^^^^^^^
  File "E:\works\hyyb\.venv\Lib\site-packages\sqlalchemy\engine\base.py", line 1287, in _execute_context
    self._handle_dbapi_exception(
  File "E:\works\hyyb\.venv\Lib\site-packages\sqlalchemy\engine\base.py", line 1481, in _handle_dbapi_exception
    util.raise_(
  File "E:\works\hyyb\.venv\Lib\site-packages\sqlalchemy\util\compat.py", line 178, in raise_
    raise exception
  File "E:\works\hyyb\.venv\Lib\site-packages\sqlalchemy\engine\base.py", line 1247, in _execute_context
    self.dialect.do_execute(
  File "E:\works\hyyb\.venv\Lib\site-packages\sqlalchemy\engine\default.py", line 588, in do_execute
    cursor.execute(statement, parameters)
sqlalchemy.exc.OperationalError: (sqlite3.OperationalError) no such table: admin
[SQL: SELECT admin.id AS admin_id, admin.username AS admin_username, admin.password_hash AS admin_password_hash, admin.privilege AS admin_privilege, admin.title AS admin_title, admin.others AS admin_others 
FROM admin
 LIMIT ? OFFSET ?]
[parameters: (1, 0)]
(Background on this error at: http://sqlalche.me/e/e3q8)
2025-04-16 21:56:20,185 - hyyb - ERROR - Exception on / [GET]
Traceback (most recent call last):
  File "E:\works\hyyb\.venv\Lib\site-packages\sqlalchemy\engine\base.py", line 1247, in _execute_context
    self.dialect.do_execute(
  File "E:\works\hyyb\.venv\Lib\site-packages\sqlalchemy\engine\default.py", line 588, in do_execute
    cursor.execute(statement, parameters)
sqlite3.OperationalError: no such table: message

The above exception was the direct cause of the following exception:

Traceback (most recent call last):
  File "E:\works\hyyb\.venv\Lib\site-packages\flask\app.py", line 2447, in wsgi_app
    response = self.full_dispatch_request()
               ^^^^^^^^^^^^^^^^^^^^^^^^^^^^
  File "E:\works\hyyb\.venv\Lib\site-packages\flask\app.py", line 1952, in full_dispatch_request
    rv = self.handle_user_exception(e)
         ^^^^^^^^^^^^^^^^^^^^^^^^^^^^^
  File "E:\works\hyyb\.venv\Lib\site-packages\flask\app.py", line 1821, in handle_user_exception
    reraise(exc_type, exc_value, tb)
  File "E:\works\hyyb\.venv\Lib\site-packages\flask\_compat.py", line 39, in reraise
    raise value
  File "E:\works\hyyb\.venv\Lib\site-packages\flask\app.py", line 1950, in full_dispatch_request
    rv = self.dispatch_request()
         ^^^^^^^^^^^^^^^^^^^^^^^
  File "E:\works\hyyb\.venv\Lib\site-packages\flask\app.py", line 1936, in dispatch_request
    return self.view_functions[rule.endpoint](**req.view_args)
           ^^^^^^^^^^^^^^^^^^^^^^^^^^^^^^^^^^^^^^^^^^^^^^^^^^^
  File "E:\works\hyyb\hyyb\blueprints\message.py", line 14, in index
    messages = Message.query.order_by(Message.timestamp.desc()).all()
               ^^^^^^^^^^^^^^^^^^^^^^^^^^^^^^^^^^^^^^^^^^^^^^^^^^^^^^
  File "E:\works\hyyb\.venv\Lib\site-packages\sqlalchemy\orm\query.py", line 3244, in all
    return list(self)
           ^^^^^^^^^^
  File "E:\works\hyyb\.venv\Lib\site-packages\sqlalchemy\orm\query.py", line 3403, in __iter__
    return self._execute_and_instances(context)
           ^^^^^^^^^^^^^^^^^^^^^^^^^^^^^^^^^^^^
  File "E:\works\hyyb\.venv\Lib\site-packages\sqlalchemy\orm\query.py", line 3428, in _execute_and_instances
    result = conn.execute(querycontext.statement, self._params)
             ^^^^^^^^^^^^^^^^^^^^^^^^^^^^^^^^^^^^^^^^^^^^^^^^^^
  File "E:\works\hyyb\.venv\Lib\site-packages\sqlalchemy\engine\base.py", line 984, in execute
    return meth(self, multiparams, params)
           ^^^^^^^^^^^^^^^^^^^^^^^^^^^^^^^
  File "E:\works\hyyb\.venv\Lib\site-packages\sqlalchemy\sql\elements.py", line 293, in _execute_on_connection
    return connection._execute_clauseelement(self, multiparams, params)
           ^^^^^^^^^^^^^^^^^^^^^^^^^^^^^^^^^^^^^^^^^^^^^^^^^^^^^^^^^^^^
  File "E:\works\hyyb\.venv\Lib\site-packages\sqlalchemy\engine\base.py", line 1097, in _execute_clauseelement
    ret = self._execute_context(
          ^^^^^^^^^^^^^^^^^^^^^^
  File "E:\works\hyyb\.venv\Lib\site-packages\sqlalchemy\engine\base.py", line 1287, in _execute_context
    self._handle_dbapi_exception(
  File "E:\works\hyyb\.venv\Lib\site-packages\sqlalchemy\engine\base.py", line 1481, in _handle_dbapi_exception
    util.raise_(
  File "E:\works\hyyb\.venv\Lib\site-packages\sqlalchemy\util\compat.py", line 178, in raise_
    raise exception
  File "E:\works\hyyb\.venv\Lib\site-packages\sqlalchemy\engine\base.py", line 1247, in _execute_context
    self.dialect.do_execute(
  File "E:\works\hyyb\.venv\Lib\site-packages\sqlalchemy\engine\default.py", line 588, in do_execute
    cursor.execute(statement, parameters)
sqlalchemy.exc.OperationalError: (sqlite3.OperationalError) no such table: message
[SQL: SELECT message.id AS message_id, message.name AS message_name, message.body AS message_body, message.timestamp AS message_timestamp, message.others AS message_others 
FROM message ORDER BY message.timestamp DESC]
(Background on this error at: http://sqlalche.me/e/e3q8)
2025-04-16 21:56:22,349 - hyyb - ERROR - Exception on /favicon.ico [GET]
Traceback (most recent call last):
  File "E:\works\hyyb\.venv\Lib\site-packages\flask\app.py", line 1950, in full_dispatch_request
    rv = self.dispatch_request()
         ^^^^^^^^^^^^^^^^^^^^^^^
  File "E:\works\hyyb\.venv\Lib\site-packages\flask\app.py", line 1926, in dispatch_request
    self.raise_routing_exception(req)
  File "E:\works\hyyb\.venv\Lib\site-packages\flask\app.py", line 1908, in raise_routing_exception
    raise request.routing_exception
  File "E:\works\hyyb\.venv\Lib\site-packages\flask\ctx.py", line 350, in match_request
    result = self.url_adapter.match(return_rule=True)
             ^^^^^^^^^^^^^^^^^^^^^^^^^^^^^^^^^^^^^^^^
  File "E:\works\hyyb\.venv\Lib\site-packages\werkzeug\routing.py", line 1945, in match
    raise NotFound()
werkzeug.exceptions.NotFound: 404 Not Found: The requested URL was not found on the server. If you entered the URL manually please check your spelling and try again.

During handling of the above exception, another exception occurred:

Traceback (most recent call last):
  File "E:\works\hyyb\.venv\Lib\site-packages\sqlalchemy\engine\base.py", line 1247, in _execute_context
    self.dialect.do_execute(
  File "E:\works\hyyb\.venv\Lib\site-packages\sqlalchemy\engine\default.py", line 588, in do_execute
    cursor.execute(statement, parameters)
sqlite3.OperationalError: no such table: admin

The above exception was the direct cause of the following exception:

Traceback (most recent call last):
  File "E:\works\hyyb\.venv\Lib\site-packages\flask\app.py", line 2447, in wsgi_app
    response = self.full_dispatch_request()
               ^^^^^^^^^^^^^^^^^^^^^^^^^^^^
  File "E:\works\hyyb\.venv\Lib\site-packages\flask\app.py", line 1952, in full_dispatch_request
    rv = self.handle_user_exception(e)
         ^^^^^^^^^^^^^^^^^^^^^^^^^^^^^
  File "E:\works\hyyb\.venv\Lib\site-packages\flask\app.py", line 1816, in handle_user_exception
    return self.handle_http_exception(e)
           ^^^^^^^^^^^^^^^^^^^^^^^^^^^^^
  File "E:\works\hyyb\.venv\Lib\site-packages\flask\app.py", line 1744, in handle_http_exception
    return handler(e)
           ^^^^^^^^^^
  File "E:\works\hyyb\hyyb\__init__.py", line 204, in page_not_found
    return render_template('errors/404.html'), 404
           ^^^^^^^^^^^^^^^^^^^^^^^^^^^^^^^^^^
  File "E:\works\hyyb\.venv\Lib\site-packages\flask\templating.py", line 136, in render_template
    ctx.app.update_template_context(context)
  File "E:\works\hyyb\.venv\Lib\site-packages\flask\app.py", line 838, in update_template_context
    context.update(func())
                   ^^^^^^
  File "E:\works\hyyb\hyyb\__init__.py", line 169, in make_template_context
    admin = Admin.query.first()
            ^^^^^^^^^^^^^^^^^^^
  File "E:\works\hyyb\.venv\Lib\site-packages\sqlalchemy\orm\query.py", line 3298, in first
    ret = list(self[0:1])
               ~~~~^^^^^
  File "E:\works\hyyb\.venv\Lib\site-packages\sqlalchemy\orm\query.py", line 3076, in __getitem__
    return list(res)
           ^^^^^^^^^
  File "E:\works\hyyb\.venv\Lib\site-packages\sqlalchemy\orm\query.py", line 3403, in __iter__
    return self._execute_and_instances(context)
           ^^^^^^^^^^^^^^^^^^^^^^^^^^^^^^^^^^^^
  File "E:\works\hyyb\.venv\Lib\site-packages\sqlalchemy\orm\query.py", line 3428, in _execute_and_instances
    result = conn.execute(querycontext.statement, self._params)
             ^^^^^^^^^^^^^^^^^^^^^^^^^^^^^^^^^^^^^^^^^^^^^^^^^^
  File "E:\works\hyyb\.venv\Lib\site-packages\sqlalchemy\engine\base.py", line 984, in execute
    return meth(self, multiparams, params)
           ^^^^^^^^^^^^^^^^^^^^^^^^^^^^^^^
  File "E:\works\hyyb\.venv\Lib\site-packages\sqlalchemy\sql\elements.py", line 293, in _execute_on_connection
    return connection._execute_clauseelement(self, multiparams, params)
           ^^^^^^^^^^^^^^^^^^^^^^^^^^^^^^^^^^^^^^^^^^^^^^^^^^^^^^^^^^^^
  File "E:\works\hyyb\.venv\Lib\site-packages\sqlalchemy\engine\base.py", line 1097, in _execute_clauseelement
    ret = self._execute_context(
          ^^^^^^^^^^^^^^^^^^^^^^
  File "E:\works\hyyb\.venv\Lib\site-packages\sqlalchemy\engine\base.py", line 1287, in _execute_context
    self._handle_dbapi_exception(
  File "E:\works\hyyb\.venv\Lib\site-packages\sqlalchemy\engine\base.py", line 1481, in _handle_dbapi_exception
    util.raise_(
  File "E:\works\hyyb\.venv\Lib\site-packages\sqlalchemy\util\compat.py", line 178, in raise_
    raise exception
  File "E:\works\hyyb\.venv\Lib\site-packages\sqlalchemy\engine\base.py", line 1247, in _execute_context
    self.dialect.do_execute(
  File "E:\works\hyyb\.venv\Lib\site-packages\sqlalchemy\engine\default.py", line 588, in do_execute
    cursor.execute(statement, parameters)
sqlalchemy.exc.OperationalError: (sqlite3.OperationalError) no such table: admin
[SQL: SELECT admin.id AS admin_id, admin.username AS admin_username, admin.password_hash AS admin_password_hash, admin.privilege AS admin_privilege, admin.title AS admin_title, admin.others AS admin_others 
FROM admin
 LIMIT ? OFFSET ?]
[parameters: (1, 0)]
(Background on this error at: http://sqlalche.me/e/e3q8)
2025-04-16 22:15:07,451 - hyyb - ERROR - Exception on / [GET]
Traceback (most recent call last):
  File "E:\works\hyyb\.venv\Lib\site-packages\sqlalchemy\engine\base.py", line 1247, in _execute_context
    self.dialect.do_execute(
  File "E:\works\hyyb\.venv\Lib\site-packages\sqlalchemy\engine\default.py", line 588, in do_execute
    cursor.execute(statement, parameters)
sqlite3.OperationalError: no such table: message

The above exception was the direct cause of the following exception:

Traceback (most recent call last):
  File "E:\works\hyyb\.venv\Lib\site-packages\flask\app.py", line 2447, in wsgi_app
    response = self.full_dispatch_request()
               ^^^^^^^^^^^^^^^^^^^^^^^^^^^^
  File "E:\works\hyyb\.venv\Lib\site-packages\flask\app.py", line 1952, in full_dispatch_request
    rv = self.handle_user_exception(e)
         ^^^^^^^^^^^^^^^^^^^^^^^^^^^^^
  File "E:\works\hyyb\.venv\Lib\site-packages\flask\app.py", line 1821, in handle_user_exception
    reraise(exc_type, exc_value, tb)
  File "E:\works\hyyb\.venv\Lib\site-packages\flask\_compat.py", line 39, in reraise
    raise value
  File "E:\works\hyyb\.venv\Lib\site-packages\flask\app.py", line 1950, in full_dispatch_request
    rv = self.dispatch_request()
         ^^^^^^^^^^^^^^^^^^^^^^^
  File "E:\works\hyyb\.venv\Lib\site-packages\flask\app.py", line 1936, in dispatch_request
    return self.view_functions[rule.endpoint](**req.view_args)
           ^^^^^^^^^^^^^^^^^^^^^^^^^^^^^^^^^^^^^^^^^^^^^^^^^^^
  File "E:\works\hyyb\hyyb\blueprints\message.py", line 14, in index
    messages = Message.query.order_by(Message.timestamp.desc()).all()
               ^^^^^^^^^^^^^^^^^^^^^^^^^^^^^^^^^^^^^^^^^^^^^^^^^^^^^^
  File "E:\works\hyyb\.venv\Lib\site-packages\sqlalchemy\orm\query.py", line 3244, in all
    return list(self)
           ^^^^^^^^^^
  File "E:\works\hyyb\.venv\Lib\site-packages\sqlalchemy\orm\query.py", line 3403, in __iter__
    return self._execute_and_instances(context)
           ^^^^^^^^^^^^^^^^^^^^^^^^^^^^^^^^^^^^
  File "E:\works\hyyb\.venv\Lib\site-packages\sqlalchemy\orm\query.py", line 3428, in _execute_and_instances
    result = conn.execute(querycontext.statement, self._params)
             ^^^^^^^^^^^^^^^^^^^^^^^^^^^^^^^^^^^^^^^^^^^^^^^^^^
  File "E:\works\hyyb\.venv\Lib\site-packages\sqlalchemy\engine\base.py", line 984, in execute
    return meth(self, multiparams, params)
           ^^^^^^^^^^^^^^^^^^^^^^^^^^^^^^^
  File "E:\works\hyyb\.venv\Lib\site-packages\sqlalchemy\sql\elements.py", line 293, in _execute_on_connection
    return connection._execute_clauseelement(self, multiparams, params)
           ^^^^^^^^^^^^^^^^^^^^^^^^^^^^^^^^^^^^^^^^^^^^^^^^^^^^^^^^^^^^
  File "E:\works\hyyb\.venv\Lib\site-packages\sqlalchemy\engine\base.py", line 1097, in _execute_clauseelement
    ret = self._execute_context(
          ^^^^^^^^^^^^^^^^^^^^^^
  File "E:\works\hyyb\.venv\Lib\site-packages\sqlalchemy\engine\base.py", line 1287, in _execute_context
    self._handle_dbapi_exception(
  File "E:\works\hyyb\.venv\Lib\site-packages\sqlalchemy\engine\base.py", line 1481, in _handle_dbapi_exception
    util.raise_(
  File "E:\works\hyyb\.venv\Lib\site-packages\sqlalchemy\util\compat.py", line 178, in raise_
    raise exception
  File "E:\works\hyyb\.venv\Lib\site-packages\sqlalchemy\engine\base.py", line 1247, in _execute_context
    self.dialect.do_execute(
  File "E:\works\hyyb\.venv\Lib\site-packages\sqlalchemy\engine\default.py", line 588, in do_execute
    cursor.execute(statement, parameters)
sqlalchemy.exc.OperationalError: (sqlite3.OperationalError) no such table: message
[SQL: SELECT message.id AS message_id, message.name AS message_name, message.body AS message_body, message.timestamp AS message_timestamp, message.others AS message_others 
FROM message ORDER BY message.timestamp DESC]
(Background on this error at: http://sqlalche.me/e/e3q8)
2025-04-16 22:15:07,509 - hyyb - ERROR - Exception on / [GET]
Traceback (most recent call last):
  File "E:\works\hyyb\.venv\Lib\site-packages\sqlalchemy\engine\base.py", line 1247, in _execute_context
    self.dialect.do_execute(
  File "E:\works\hyyb\.venv\Lib\site-packages\sqlalchemy\engine\default.py", line 588, in do_execute
    cursor.execute(statement, parameters)
sqlite3.OperationalError: no such table: message

The above exception was the direct cause of the following exception:

Traceback (most recent call last):
  File "E:\works\hyyb\.venv\Lib\site-packages\flask\app.py", line 2447, in wsgi_app
    response = self.full_dispatch_request()
               ^^^^^^^^^^^^^^^^^^^^^^^^^^^^
  File "E:\works\hyyb\.venv\Lib\site-packages\flask\app.py", line 1952, in full_dispatch_request
    rv = self.handle_user_exception(e)
         ^^^^^^^^^^^^^^^^^^^^^^^^^^^^^
  File "E:\works\hyyb\.venv\Lib\site-packages\flask\app.py", line 1821, in handle_user_exception
    reraise(exc_type, exc_value, tb)
  File "E:\works\hyyb\.venv\Lib\site-packages\flask\_compat.py", line 39, in reraise
    raise value
  File "E:\works\hyyb\.venv\Lib\site-packages\flask\app.py", line 1950, in full_dispatch_request
    rv = self.dispatch_request()
         ^^^^^^^^^^^^^^^^^^^^^^^
  File "E:\works\hyyb\.venv\Lib\site-packages\flask\app.py", line 1936, in dispatch_request
    return self.view_functions[rule.endpoint](**req.view_args)
           ^^^^^^^^^^^^^^^^^^^^^^^^^^^^^^^^^^^^^^^^^^^^^^^^^^^
  File "E:\works\hyyb\hyyb\blueprints\message.py", line 14, in index
    messages = Message.query.order_by(Message.timestamp.desc()).all()
               ^^^^^^^^^^^^^^^^^^^^^^^^^^^^^^^^^^^^^^^^^^^^^^^^^^^^^^
  File "E:\works\hyyb\.venv\Lib\site-packages\sqlalchemy\orm\query.py", line 3244, in all
    return list(self)
           ^^^^^^^^^^
  File "E:\works\hyyb\.venv\Lib\site-packages\sqlalchemy\orm\query.py", line 3403, in __iter__
    return self._execute_and_instances(context)
           ^^^^^^^^^^^^^^^^^^^^^^^^^^^^^^^^^^^^
  File "E:\works\hyyb\.venv\Lib\site-packages\sqlalchemy\orm\query.py", line 3428, in _execute_and_instances
    result = conn.execute(querycontext.statement, self._params)
             ^^^^^^^^^^^^^^^^^^^^^^^^^^^^^^^^^^^^^^^^^^^^^^^^^^
  File "E:\works\hyyb\.venv\Lib\site-packages\sqlalchemy\engine\base.py", line 984, in execute
    return meth(self, multiparams, params)
           ^^^^^^^^^^^^^^^^^^^^^^^^^^^^^^^
  File "E:\works\hyyb\.venv\Lib\site-packages\sqlalchemy\sql\elements.py", line 293, in _execute_on_connection
    return connection._execute_clauseelement(self, multiparams, params)
           ^^^^^^^^^^^^^^^^^^^^^^^^^^^^^^^^^^^^^^^^^^^^^^^^^^^^^^^^^^^^
  File "E:\works\hyyb\.venv\Lib\site-packages\sqlalchemy\engine\base.py", line 1097, in _execute_clauseelement
    ret = self._execute_context(
          ^^^^^^^^^^^^^^^^^^^^^^
  File "E:\works\hyyb\.venv\Lib\site-packages\sqlalchemy\engine\base.py", line 1287, in _execute_context
    self._handle_dbapi_exception(
  File "E:\works\hyyb\.venv\Lib\site-packages\sqlalchemy\engine\base.py", line 1481, in _handle_dbapi_exception
    util.raise_(
  File "E:\works\hyyb\.venv\Lib\site-packages\sqlalchemy\util\compat.py", line 178, in raise_
    raise exception
  File "E:\works\hyyb\.venv\Lib\site-packages\sqlalchemy\engine\base.py", line 1247, in _execute_context
    self.dialect.do_execute(
  File "E:\works\hyyb\.venv\Lib\site-packages\sqlalchemy\engine\default.py", line 588, in do_execute
    cursor.execute(statement, parameters)
sqlalchemy.exc.OperationalError: (sqlite3.OperationalError) no such table: message
[SQL: SELECT message.id AS message_id, message.name AS message_name, message.body AS message_body, message.timestamp AS message_timestamp, message.others AS message_others 
FROM message ORDER BY message.timestamp DESC]
(Background on this error at: http://sqlalche.me/e/e3q8)
2025-04-16 22:15:07,589 - hyyb - ERROR - Exception on /favicon.ico [GET]
Traceback (most recent call last):
  File "E:\works\hyyb\.venv\Lib\site-packages\flask\app.py", line 1950, in full_dispatch_request
    rv = self.dispatch_request()
         ^^^^^^^^^^^^^^^^^^^^^^^
  File "E:\works\hyyb\.venv\Lib\site-packages\flask\app.py", line 1926, in dispatch_request
    self.raise_routing_exception(req)
  File "E:\works\hyyb\.venv\Lib\site-packages\flask\app.py", line 1908, in raise_routing_exception
    raise request.routing_exception
  File "E:\works\hyyb\.venv\Lib\site-packages\flask\ctx.py", line 350, in match_request
    result = self.url_adapter.match(return_rule=True)
             ^^^^^^^^^^^^^^^^^^^^^^^^^^^^^^^^^^^^^^^^
  File "E:\works\hyyb\.venv\Lib\site-packages\werkzeug\routing.py", line 1945, in match
    raise NotFound()
werkzeug.exceptions.NotFound: 404 Not Found: The requested URL was not found on the server. If you entered the URL manually please check your spelling and try again.

During handling of the above exception, another exception occurred:

Traceback (most recent call last):
  File "E:\works\hyyb\.venv\Lib\site-packages\sqlalchemy\engine\base.py", line 1247, in _execute_context
    self.dialect.do_execute(
  File "E:\works\hyyb\.venv\Lib\site-packages\sqlalchemy\engine\default.py", line 588, in do_execute
    cursor.execute(statement, parameters)
sqlite3.OperationalError: no such table: admin

The above exception was the direct cause of the following exception:

Traceback (most recent call last):
  File "E:\works\hyyb\.venv\Lib\site-packages\flask\app.py", line 2447, in wsgi_app
    response = self.full_dispatch_request()
               ^^^^^^^^^^^^^^^^^^^^^^^^^^^^
  File "E:\works\hyyb\.venv\Lib\site-packages\flask\app.py", line 1952, in full_dispatch_request
    rv = self.handle_user_exception(e)
         ^^^^^^^^^^^^^^^^^^^^^^^^^^^^^
  File "E:\works\hyyb\.venv\Lib\site-packages\flask\app.py", line 1816, in handle_user_exception
    return self.handle_http_exception(e)
           ^^^^^^^^^^^^^^^^^^^^^^^^^^^^^
  File "E:\works\hyyb\.venv\Lib\site-packages\flask\app.py", line 1744, in handle_http_exception
    return handler(e)
           ^^^^^^^^^^
  File "E:\works\hyyb\hyyb\__init__.py", line 204, in page_not_found
    return render_template('errors/404.html'), 404
           ^^^^^^^^^^^^^^^^^^^^^^^^^^^^^^^^^^
  File "E:\works\hyyb\.venv\Lib\site-packages\flask\templating.py", line 136, in render_template
    ctx.app.update_template_context(context)
  File "E:\works\hyyb\.venv\Lib\site-packages\flask\app.py", line 838, in update_template_context
    context.update(func())
                   ^^^^^^
  File "E:\works\hyyb\hyyb\__init__.py", line 169, in make_template_context
    admin = Admin.query.first()
            ^^^^^^^^^^^^^^^^^^^
  File "E:\works\hyyb\.venv\Lib\site-packages\sqlalchemy\orm\query.py", line 3298, in first
    ret = list(self[0:1])
               ~~~~^^^^^
  File "E:\works\hyyb\.venv\Lib\site-packages\sqlalchemy\orm\query.py", line 3076, in __getitem__
    return list(res)
           ^^^^^^^^^
  File "E:\works\hyyb\.venv\Lib\site-packages\sqlalchemy\orm\query.py", line 3403, in __iter__
    return self._execute_and_instances(context)
           ^^^^^^^^^^^^^^^^^^^^^^^^^^^^^^^^^^^^
  File "E:\works\hyyb\.venv\Lib\site-packages\sqlalchemy\orm\query.py", line 3428, in _execute_and_instances
    result = conn.execute(querycontext.statement, self._params)
             ^^^^^^^^^^^^^^^^^^^^^^^^^^^^^^^^^^^^^^^^^^^^^^^^^^
  File "E:\works\hyyb\.venv\Lib\site-packages\sqlalchemy\engine\base.py", line 984, in execute
    return meth(self, multiparams, params)
           ^^^^^^^^^^^^^^^^^^^^^^^^^^^^^^^
  File "E:\works\hyyb\.venv\Lib\site-packages\sqlalchemy\sql\elements.py", line 293, in _execute_on_connection
    return connection._execute_clauseelement(self, multiparams, params)
           ^^^^^^^^^^^^^^^^^^^^^^^^^^^^^^^^^^^^^^^^^^^^^^^^^^^^^^^^^^^^
  File "E:\works\hyyb\.venv\Lib\site-packages\sqlalchemy\engine\base.py", line 1097, in _execute_clauseelement
    ret = self._execute_context(
          ^^^^^^^^^^^^^^^^^^^^^^
  File "E:\works\hyyb\.venv\Lib\site-packages\sqlalchemy\engine\base.py", line 1287, in _execute_context
    self._handle_dbapi_exception(
  File "E:\works\hyyb\.venv\Lib\site-packages\sqlalchemy\engine\base.py", line 1481, in _handle_dbapi_exception
    util.raise_(
  File "E:\works\hyyb\.venv\Lib\site-packages\sqlalchemy\util\compat.py", line 178, in raise_
    raise exception
  File "E:\works\hyyb\.venv\Lib\site-packages\sqlalchemy\engine\base.py", line 1247, in _execute_context
    self.dialect.do_execute(
  File "E:\works\hyyb\.venv\Lib\site-packages\sqlalchemy\engine\default.py", line 588, in do_execute
    cursor.execute(statement, parameters)
sqlalchemy.exc.OperationalError: (sqlite3.OperationalError) no such table: admin
[SQL: SELECT admin.id AS admin_id, admin.username AS admin_username, admin.password_hash AS admin_password_hash, admin.privilege AS admin_privilege, admin.title AS admin_title, admin.others AS admin_others 
FROM admin
 LIMIT ? OFFSET ?]
[parameters: (1, 0)]
(Background on this error at: http://sqlalche.me/e/e3q8)
2025-04-16 22:15:07,690 - hyyb - ERROR - Exception on /favicon.ico [GET]
Traceback (most recent call last):
  File "E:\works\hyyb\.venv\Lib\site-packages\flask\app.py", line 1950, in full_dispatch_request
    rv = self.dispatch_request()
         ^^^^^^^^^^^^^^^^^^^^^^^
  File "E:\works\hyyb\.venv\Lib\site-packages\flask\app.py", line 1926, in dispatch_request
    self.raise_routing_exception(req)
  File "E:\works\hyyb\.venv\Lib\site-packages\flask\app.py", line 1908, in raise_routing_exception
    raise request.routing_exception
  File "E:\works\hyyb\.venv\Lib\site-packages\flask\ctx.py", line 350, in match_request
    result = self.url_adapter.match(return_rule=True)
             ^^^^^^^^^^^^^^^^^^^^^^^^^^^^^^^^^^^^^^^^
  File "E:\works\hyyb\.venv\Lib\site-packages\werkzeug\routing.py", line 1945, in match
    raise NotFound()
werkzeug.exceptions.NotFound: 404 Not Found: The requested URL was not found on the server. If you entered the URL manually please check your spelling and try again.

During handling of the above exception, another exception occurred:

Traceback (most recent call last):
  File "E:\works\hyyb\.venv\Lib\site-packages\sqlalchemy\engine\base.py", line 1247, in _execute_context
    self.dialect.do_execute(
  File "E:\works\hyyb\.venv\Lib\site-packages\sqlalchemy\engine\default.py", line 588, in do_execute
    cursor.execute(statement, parameters)
sqlite3.OperationalError: no such table: admin

The above exception was the direct cause of the following exception:

Traceback (most recent call last):
  File "E:\works\hyyb\.venv\Lib\site-packages\flask\app.py", line 2447, in wsgi_app
    response = self.full_dispatch_request()
               ^^^^^^^^^^^^^^^^^^^^^^^^^^^^
  File "E:\works\hyyb\.venv\Lib\site-packages\flask\app.py", line 1952, in full_dispatch_request
    rv = self.handle_user_exception(e)
         ^^^^^^^^^^^^^^^^^^^^^^^^^^^^^
  File "E:\works\hyyb\.venv\Lib\site-packages\flask\app.py", line 1816, in handle_user_exception
    return self.handle_http_exception(e)
           ^^^^^^^^^^^^^^^^^^^^^^^^^^^^^
  File "E:\works\hyyb\.venv\Lib\site-packages\flask\app.py", line 1744, in handle_http_exception
    return handler(e)
           ^^^^^^^^^^
  File "E:\works\hyyb\hyyb\__init__.py", line 204, in page_not_found
    return render_template('errors/404.html'), 404
           ^^^^^^^^^^^^^^^^^^^^^^^^^^^^^^^^^^
  File "E:\works\hyyb\.venv\Lib\site-packages\flask\templating.py", line 136, in render_template
    ctx.app.update_template_context(context)
  File "E:\works\hyyb\.venv\Lib\site-packages\flask\app.py", line 838, in update_template_context
    context.update(func())
                   ^^^^^^
  File "E:\works\hyyb\hyyb\__init__.py", line 169, in make_template_context
    admin = Admin.query.first()
            ^^^^^^^^^^^^^^^^^^^
  File "E:\works\hyyb\.venv\Lib\site-packages\sqlalchemy\orm\query.py", line 3298, in first
    ret = list(self[0:1])
               ~~~~^^^^^
  File "E:\works\hyyb\.venv\Lib\site-packages\sqlalchemy\orm\query.py", line 3076, in __getitem__
    return list(res)
           ^^^^^^^^^
  File "E:\works\hyyb\.venv\Lib\site-packages\sqlalchemy\orm\query.py", line 3403, in __iter__
    return self._execute_and_instances(context)
           ^^^^^^^^^^^^^^^^^^^^^^^^^^^^^^^^^^^^
  File "E:\works\hyyb\.venv\Lib\site-packages\sqlalchemy\orm\query.py", line 3428, in _execute_and_instances
    result = conn.execute(querycontext.statement, self._params)
             ^^^^^^^^^^^^^^^^^^^^^^^^^^^^^^^^^^^^^^^^^^^^^^^^^^
  File "E:\works\hyyb\.venv\Lib\site-packages\sqlalchemy\engine\base.py", line 984, in execute
    return meth(self, multiparams, params)
           ^^^^^^^^^^^^^^^^^^^^^^^^^^^^^^^
  File "E:\works\hyyb\.venv\Lib\site-packages\sqlalchemy\sql\elements.py", line 293, in _execute_on_connection
    return connection._execute_clauseelement(self, multiparams, params)
           ^^^^^^^^^^^^^^^^^^^^^^^^^^^^^^^^^^^^^^^^^^^^^^^^^^^^^^^^^^^^
  File "E:\works\hyyb\.venv\Lib\site-packages\sqlalchemy\engine\base.py", line 1097, in _execute_clauseelement
    ret = self._execute_context(
          ^^^^^^^^^^^^^^^^^^^^^^
  File "E:\works\hyyb\.venv\Lib\site-packages\sqlalchemy\engine\base.py", line 1287, in _execute_context
    self._handle_dbapi_exception(
  File "E:\works\hyyb\.venv\Lib\site-packages\sqlalchemy\engine\base.py", line 1481, in _handle_dbapi_exception
    util.raise_(
  File "E:\works\hyyb\.venv\Lib\site-packages\sqlalchemy\util\compat.py", line 178, in raise_
    raise exception
  File "E:\works\hyyb\.venv\Lib\site-packages\sqlalchemy\engine\base.py", line 1247, in _execute_context
    self.dialect.do_execute(
  File "E:\works\hyyb\.venv\Lib\site-packages\sqlalchemy\engine\default.py", line 588, in do_execute
    cursor.execute(statement, parameters)
sqlalchemy.exc.OperationalError: (sqlite3.OperationalError) no such table: admin
[SQL: SELECT admin.id AS admin_id, admin.username AS admin_username, admin.password_hash AS admin_password_hash, admin.privilege AS admin_privilege, admin.title AS admin_title, admin.others AS admin_others 
FROM admin
 LIMIT ? OFFSET ?]
[parameters: (1, 0)]
(Background on this error at: http://sqlalche.me/e/e3q8)
